Workbook

Sheet Kontrak
A1: v
A2: Tugas pendahuluan dan respon | B2: 0.2
A3: Laporan | B3: 0.3
A4: Keaktifan | B4: 0.1
A5: Final | B5: 0.3
A6: Kehadiran | B6: 0.1

Sheet KELAS B
A1: KELAS B
A5: NIM | B5: NAMA | C5: Kehadiran | M5: Nilai Kehadiran | N5: Keaktifan | X5: Nilai Keaktifan | Y5: Tugas Pendahuluan | AG5: Nilai TP | AH5: Laporan | AP5: Nilai Laporan | AQ5: Nilai UAS | AR5: Nilai Hasil | AS5: LP Ass1 | BA5: LP Ass2
C6: 1 | D6: 2 | E6: 3 | F6: 4 | G6: 5 | H6: 6 | I6: 7 | J6: 8 | K6: 9 | L6: 10 | N6: 1 | O6: 2 | P6: 3 | Q6: 4 | R6: 5 | S6: 6 | T6: 7 | U6: 8 | V6: 9 | W6: 10 | Y6: 1 | Z6: 2 | AA6: 3 | AB6: 4 | AC6: 5 | AD6: 6 | AE6: 7 | AF6: 8 | AH6: 1 | AI6: 2 | AJ6: 3 | AK6: 4 | AL6: 5 | AM6: 6 | AN6: 7 | AO6: 8 | AS6: 1 | AT6: 2 | AU6: 3 | AV6: 4 | AW6: 5 | AX6: 6 | AY6: 7 | AZ6: 8 | BA6: 1 | BB6: 2 | BC6: 3 | BD6: 4 | BE6: 5 | BF6: 6 | BG6: 7 | BH6: 8
A7: 60200125002 | B7: AHMAD FAUZI ALI | D7: 1 | E7: 1 | F7: =IF(AA7>0,1,0) -> 0 | G7: =IF(AB7>0,1,0) -> 0 | H7: =IF(AC7>0,1,0) -> 0 | I7: =IF(AD7>0,1,0) -> 1 | J7: =IF(AE7>0,1,0) -> 0 | M7: =SUM(C7:L7)*10 -> 30 | N7: 0 | O7: 0 | P7: 0 | Q7: 0 | R7: 0 | S7: 0 | T7: 0 | U7: 0 | V7: 0 | W7: 0 | X7: =SUM(N7:W7)/10 -> 0 | Y7: 0 | Z7: 0 | AA7: 0 | AB7: 0 | AC7: 0 | AD7: 100 | AE7: 0 | AF7: 0 | AG7: =SUM(Y7:AF7)/7 -> 14.285714 | AH7: 0 | AI7: 0 | AJ7: 0 | AK7: 0 | AL7: 0 | AM7: 0 | AN7: 0 | AO7: 0 | AP7: =SUM(AH7:AO7)/7 -> 0 | AQ7: =IFERROR(VLOOKUP(A7, PENILAIAN_UAS!A2:B111, 2, FALSE), "NULL") -> 0 | AR7: =(Kontrak!$B$6*M7)+(Kontrak!$B$4*X7)+(Kontrak!$B$2*AG7)+(Kontrak!$B$3*AP7)+(Kontrak!$B$5*AQ7) -> 5.8571429
A8: 60200125008 | B8: RAGIL ANGGINO | D8: 1 | E8: 1 | F8: =IF(AA8>0,1,0) -> 0 | G8: =IF(AB8>0,1,0) -> 0 | H8: =IF(AC8>0,1,0) -> 0 | I8: =IF(AD8>0,1,0) -> 1 | J8: =IF(AE8>0,1,0) -> 0 | M8: =SUM(C8:L8)*10 -> 30 | N8: 0 | O8: 0 | P8: 0 | Q8: 0 | R8: 0 | S8: 0 | T8: 0 | U8: 0 | V8: 0 | W8: 0 | X8: =SUM(N8:W8)/10 -> 0 | Y8: 0 | Z8: 0 | AA8: 0 | AB8: 0 | AC8: 0 | AD8: 100 | AE8: 0 | AF8: 0 | AG8: =SUM(Y8:AF8)/7 -> 14.285714 | AH8: 0 | AI8: 0 | AJ8: 0 | AK8: 0 | AL8: 0 | AM8: 0 | AN8: 0 | AO8: 0 | AP8: =SUM(AH8:AO8)/7 -> 0 | AQ8: =IFERROR(VLOOKUP(A8, PENILAIAN_UAS!A3:B112, 2, FALSE), "NULL") -> 0 | AR8: =(Kontrak!$B$6*M8)+(Kontrak!$B$4*X8)+(Kontrak!$B$2*AG8)+(Kontrak!$B$3*AP8)+(Kontrak!$B$5*AQ8) -> 5.8571429
A9: 60200125009 | B9: MUHAMMAD AJIS UMAR | C9: 1 | D9: 1 | E9: 1 | F9: =IF(AA9>0,1,0) -> 1 | G9: =IF(AB9>0,1,0) -> 1 | H9: =IF(AC9>0,1,0) -> 1 | I9: =IF(AD9>0,1,0) -> 1 | J9: =IF(AE9>0,1,0) -> 1 | M9: =SUM(C9:L9)*10 -> 80 | N9: 0 | O9: 0 | P9: 0 | Q9: 100 | R9: 0 | S9: 0 | T9: 0 | U9: 0 | V9: 0 | W9: 100 | X9: =SUM(N9:W9)/10 -> 20 | Y9: 80 | Z9: 100 | AA9: 83 | AB9: 85 | AC9: 86 | AD9: 100 | AE9: 86 | AF9: 87 | AG9: =SUM(Y9:AF9)/7 -> 101 | AH9: =(AS9+BA9)/2 -> 90 | AI9: 80 | AJ9: =(AU9+BC9)/2 -> 85.5 | AK9: =(AV9+BD9)/2 -> 43 | AL9: =(AW9+BE9)/2 -> 42.5 | AM9: =(AX9+BF9)/2 -> 42.5 | AN9: =(AY9+BG9)/2 -> 42.5 | AO9: =(AZ9+BH9)/2 -> 43 | AP9: =SUM(AH9:AO9)/7 -> 67 | AQ9: =IFERROR(VLOOKUP(A9, PENILAIAN_UAS!A4:B113, 2, FALSE), "NULL") -> 84 | AR9: 80 | AS9: 89 | AT9: 84 | AU9: 80 | AV9: 86 | AW9: 85 | AX9: 85 | AY9: 85 | AZ9: 86 | BA9: 91 | BB9: 91 | BC9: 91
A10: 60200125019 | B10: MULIA PAMBUDI DIVANSYAH GAFFANG | C10: 1 | D10: 1 | E10: 1 | F10: =IF(AA10>0,1,0) -> 1 | G10: =IF(AB10>0,1,0) -> 1 | H10: =IF(AC10>0,1,0) -> 1 | I10: =IF(AD10>0,1,0) -> 1 | J10: =IF(AE10>0,1,0) -> 1 | M10: =SUM(C10:L10)*10 -> 80 | N10: 0 | O10: 0 | P10: 0 | Q10: 90 | R10: 0 | S10: 0 | T10: 0 | U10: 0 | V10: 0 | W10: 100 | X10: =SUM(N10:W10)/10 -> 19 | Y10: 80 | Z10: 100 | AA10: 83 | AB10: 100 | AC10: 86 | AD10: 100 | AE10: 87 | AF10: 100 | AG10: =SUM(Y10:AF10)/7 -> 105.14286 | AH10: =(AS10+BA10)/2 -> 88 | AI10: 87 | AJ10: =(AU10+BC10)/2 -> 90 | AK10: =(AV10+BD10)/2 -> 88.5 | AL10: =(AW10+BE10)/2 -> 85.5 | AM10: =(AX10+BF10)/2 -> 88 | AN10: =(AY10+BG10)/2 -> 43 | AO10: =(AZ10+BH10)/2 -> 41.5 | AP10: =SUM(AH10:AO10)/7 -> 87.357143 | AQ10: =IFERROR(VLOOKUP(A10, PENILAIAN_UAS!A5:B114, 2, FALSE), "NULL") -> 87 | AR10: =(Kontrak!$B$6*M10)+(Kontrak!$B$4*X10)+(Kontrak!$B$2*AG10)+(Kontrak!$B$3*AP10)+(Kontrak!$B$5*AQ10) -> 83.235714 | AS10: 85 | AT10: 85 | AU10: 89 | AV10: 86 | AW10: 80 | AX10: 85 | AY10: 86 | AZ10: 83 | BA10: 91 | BB10: 91 | BC10: 91 | BD10: 91 | BE10: 91 | BF10: 91
A11: 60200125020 | B11: DEA ASTUTI | C11: 1 | D11: 1 | E11: 1 | F11: =IF(AA11>0,1,0) -> 1 | G11: =IF(AB11>0,1,0) -> 1 | H11: =IF(AC11>0,1,0) -> 1 | I11: =IF(AD11>0,1,0) -> 1 | J11: =IF(AE11>0,1,0) -> 1 | M11: =SUM(C11:L11)*10 -> 80 | N11: 0 | O11: 0 | P11: 0 | Q11: 90 | R11: 0 | S11: 0 | T11: 0 | U11: 0 | V11: 0 | W11: 100 | X11: =SUM(N11:W11)/10 -> 19 | Y11: 100 | Z11: 80 | AA11: 100 | AB11: 80 | AC11: 100 | AD11: 100 | AE11: 100 | AF11: 87 | AG11: =SUM(Y11:AF11)/7 -> 106.71429 | AH11: =(AS11+BA11)/2 -> 90 | AI11: =(AT11+BB11)/2 -> 88 | AJ11: =(AU11+BC11)/2 -> 89.5 | AK11: =(AV11+BD11)/2 -> 88.5 | AL11: =(AW11+BE11)/2 -> 88 | AM11: =(AX11+BF11)/2 -> 88.5 | AN11: =(AY11+BG11)/2 -> 43 | AO11: =(AZ11+BH11)/2 -> 42.5 | AP11: =SUM(AH11:AO11)/7 -> 88.285714 | AQ11: =IFERROR(VLOOKUP(A11, PENILAIAN_UAS!A6:B115, 2, FALSE), "NULL") -> 89 | AR11: =(Kontrak!$B$6*M11)+(Kontrak!$B$4*X11)+(Kontrak!$B$2*AG11)+(Kontrak!$B$3*AP11)+(Kontrak!$B$5*AQ11) -> 84.428571 | AS11: 89 | AT11: 85 | AU11: 88 | AV11: 86 | AW11: 85 | AX11: 86 | AY11: 86 | AZ11: 85 | BA11: 91 | BB11: 91 | BC11: 91 | BD11: 91 | BE11: 91 | BF11: 91
A12: 60200125021 | B12: MUHAMMAD ALIM HIDAYATULLAH | C12: 1 | D12: 1 | E12: 1 | F12: =IF(AA12>0,1,0) -> 1 | G12: =IF(AB12>0,1,0) -> 1 | H12: =IF(AC12>0,1,0) -> 1 | I12: =IF(AD12>0,1,0) -> 1 | J12: =IF(AE12>0,1,0) -> 1 | M12: =SUM(C12:L12)*10 -> 80 | N12: 0 | O12: 0 | P12: 0 | Q12: 90 | R12: 0 | S12: 0 | T12: 0 | U12: 0 | V12: 0 | W12: 100 | X12: =SUM(N12:W12)/10 -> 19 | Y12: 85 | Z12: 100 | AA12: 80 | AB12: 100 | AC12: 86 | AD12: 100 | AE12: 87 | AF12: 100 | AG12: =SUM(Y12:AF12)/7 -> 105.42857 | AH12: =(AS12+BA12)/2 -> 90 | AI12: 81 | AJ12: =(AU12+BC12)/2 -> 90 | AK12: =(AV12+BD12)/2 -> 89.5 | AL12: =(AW12+BE12)/2 -> 87 | AM12: =(AX12+BF12)/2 -> 85.5 | AN12: =(AY12+BG12)/2 -> 84.5 | AO12: =(AZ12+BH12)/2 -> 83.5 | AP12: =SUM(AH12:AO12)/7 -> 98.714286 | AQ12: =IFERROR(VLOOKUP(A12, PENILAIAN_UAS!A7:B116, 2, FALSE), "NULL") -> 84 | AR12: =(Kontrak!$B$6*M12)+(Kontrak!$B$4*X12)+(Kontrak!$B$2*AG12)+(Kontrak!$B$3*AP12)+(Kontrak!$B$5*AQ12) -> 85.8 | AS12: 89 | AU12: 89 | AV12: 88 | AW12: 83 | AX12: 80 | AY12: 85 | AZ12: 83 | BA12: 91 | BB12: 91 | BC12: 91 | BD12: 91 | BE12: 91 | BF12: 91 | BG12: 84 | BH12: 84
A13: 60200125035 | B13: NISA ULHAMIDA | C13: 1 | D13: 1 | E13: 1 | F13: =IF(AA13>0,1,0) -> 0 | G13: =IF(AB13>0,1,0) -> 1 | H13: =IF(AC13>0,1,0) -> 1 | I13: =IF(AD13>0,1,0) -> 1 | J13: =IF(AE13>0,1,0) -> 1 | M13: =SUM(C13:L13)*10 -> 70 | N13: 0 | O13: 0 | P13: 0 | Q13: 0 | R13: 0 | S13: 0 | T13: 0 | U13: 0 | V13: 0 | W13: 100 | X13: =SUM(N13:W13)/10 -> 10 | Y13: 83 | Z13: 100 | AA13: 0 | AB13: 100 | AC13: 83 | AD13: 100 | AE13: 87 | AF13: 100 | AG13: =SUM(Y13:AF13)/7 -> 93.285714 | AH13: =(AS13+BA13)/2 -> 45.5 | AI13: =(AT13+BB13)/2 -> 85.5 | AJ13: =(AU13+BC13)/2 -> 88 | AK13: =(AV13+BD13)/2 -> 42 | AL13: =(AW13+BE13)/2 -> 42 | AM13: =(AX13+BF13)/2 -> 42.5 | AN13: =(AY13+BG13)/2 -> 41 | AO13: =(AZ13+BH13)/2 -> 43 | AP13: =SUM(AH13:AO13)/7 -> 61.357143 | AQ13: =IFERROR(VLOOKUP(A13, PENILAIAN_UAS!A8:B117, 2, FALSE), "NULL") -> 91 | AR13: 80 | AT13: 80 | AU13: 85 | AV13: 84 | AW13: 84 | AX13: 85 | AY13: 82 | AZ13: 86 | BA13: 91 | BB13: 91 | BC13: 91
A14: 60200125036 | B14: HENDRYANSYAH | C14: 1 | D14: 1 | E14: 1 | F14: =IF(AA14>0,1,0) -> 1 | G14: =IF(AB14>0,1,0) -> 1 | H14: =IF(AC14>0,1,0) -> 1 | I14: =IF(AD14>0,1,0) -> 1 | J14: =IF(AE14>0,1,0) -> 1 | M14: =SUM(C14:L14)*10 -> 80 | N14: 0 | O14: 0 | P14: 0 | Q14: 0 | R14: 0 | S14: 0 | T14: 0 | U14: 0 | V14: 0 | W14: 100 | X14: =SUM(N14:W14)/10 -> 10 | Y14: 100 | Z14: 80 | AA14: 100 | AB14: 82 | AC14: 100 | AD14: 100 | AE14: 100 | AF14: 87 | AG14: =SUM(Y14:AF14)/7 -> 107 | AH14: =(AS14+BA14)/2 -> 87 | AI14: 83 | AJ14: =(AU14+BC14)/2 -> 40 | AK14: =(AV14+BD14)/2 -> 41 | AL14: =(AW14+BE14)/2 -> 35 | AM14: =(AX14+BF14)/2 -> 40 | AN14: =(AY14+BG14)/2 -> 41 | AO14: =(AZ14+BH14)/2 -> 0 | AP14: =SUM(AH14:AO14)/7 -> 52.428571 | AQ14: =IFERROR(VLOOKUP(A14, PENILAIAN_UAS!A9:B118, 2, FALSE), "NULL") -> 0 | AR14: =(Kontrak!$B$6*M14)+(Kontrak!$B$4*X14)+(Kontrak!$B$2*AG14)+(Kontrak!$B$3*AP14)+(Kontrak!$B$5*AQ14) -> 46.128571 | AS14: 83 | AT14: 80 | AU14: 80 | AV14: 82 | AW14: 70 | AX14: 80 | AY14: 82 | BA14: 91
A15: 60200125048 | B15: SITI HABIBA | C15: 1 | D15: 1 | E15: 1 | F15: =IF(AA15>0,1,0) -> 1 | G15: =IF(AB15>0,1,0) -> 1 | H15: =IF(AC15>0,1,0) -> 1 | I15: =IF(AD15>0,1,0) -> 1 | J15: =IF(AE15>0,1,0) -> 1 | M15: =SUM(C15:L15)*10 -> 80 | N15: 0 | O15: 0 | P15: 0 | Q15: 0 | R15: 0 | S15: 0 | T15: 0 | U15: 0 | V15: 0 | W15: 100 | X15: =SUM(N15:W15)/10 -> 10 | Y15: 100 | Z15: 0 | AA15: 100 | AB15: 80 | AC15: 100 | AD15: 100 | AE15: 87 | AF15: 87 | AG15: =SUM(Y15:AF15)/7 -> 93.428571 | AH15: =(AS15+BA15)/2 -> 90 | AI15: =(AT15+BB15)/2 -> 42.5 | AJ15: =(AU15+BC15)/2 -> 42 | AK15: =(AV15+BD15)/2 -> 41.5 | AL15: =(AW15+BE15)/2 -> 42.5 | AM15: =(AX15+BF15)/2 -> 42.5 | AN15: =(AY15+BG15)/2 -> 43 | AO15: =(AZ15+BH15)/2 -> 43 | AP15: =SUM(AH15:AO15)/7 -> 55.285714 | AQ15: =IFERROR(VLOOKUP(A15, PENILAIAN_UAS!A10:B119, 2, FALSE), "NULL") -> 87 | AR15: 80 | AS15: 89 | AT15: 85 | AU15: 84 | AV15: 83 | AW15: 85 | AX15: 85 | AY15: 86 | AZ15: 86 | BA15: 91
A16: 60200125054 | B16: MUH. RAIHAN ARIEF CAMA | D16: 1 | E16: 1 | F16: =IF(AA16>0,1,0) -> 0 | G16: =IF(AB16>0,1,0) -> 0 | H16: =IF(AC16>0,1,0) -> 0 | I16: =IF(AD16>0,1,0) -> 1 | J16: =IF(AE16>0,1,0) -> 0 | M16: =SUM(C16:L16)*10 -> 30 | N16: 0 | O16: 0 | P16: 0 | Q16: 0 | R16: 0 | S16: 0 | T16: 0 | U16: 0 | V16: 0 | W16: 100 | X16: =SUM(N16:W16)/10 -> 10 | Y16: 0 | Z16: 0 | AA16: 0 | AB16: 0 | AC16: 0 | AD16: 100 | AE16: 0 | AF16: 0 | AG16: =SUM(Y16:AF16)/7 -> 14.285714 | AH16: =(AS16+BA16)/2 -> 0 | AI16: =(AT16+BB16)/2 -> 0 | AJ16: =(AU16+BC16)/2 -> 0 | AK16: =(AV16+BD16)/2 -> 0 | AL16: =(AW16+BE16)/2 -> 0 | AM16: =(AX16+BF16)/2 -> 0 | AN16: =(AY16+BG16)/2 -> 0 | AO16: =(AZ16+BH16)/2 -> 0 | AP16: =SUM(AH16:AO16)/7 -> 0 | AQ16: =IFERROR(VLOOKUP(A16, PENILAIAN_UAS!A11:B120, 2, FALSE), "NULL") -> 87 | AR16: =(Kontrak!$B$6*M16)+(Kontrak!$B$4*X16)+(Kontrak!$B$2*AG16)+(Kontrak!$B$3*AP16)+(Kontrak!$B$5*AQ16) -> 32.957143
A17: 60200125055 | B17: NURHAKIKI | C17: 1 | D17: 1 | E17: 1 | F17: =IF(AA17>0,1,0) -> 1 | G17: =IF(AB17>0,1,0) -> 1 | H17: =IF(AC17>0,1,0) -> 1 | I17: =IF(AD17>0,1,0) -> 1 | J17: =IF(AE17>0,1,0) -> 1 | M17: =SUM(C17:L17)*10 -> 80 | N17: 0 | O17: 0 | P17: 0 | Q17: 0 | R17: 0 | S17: 0 | T17: 0 | U17: 0 | V17: 0 | W17: 0 | X17: =SUM(N17:W17)/10 -> 0 | Y17: 80 | Z17: 100 | AA17: 80 | AB17: 100 | AC17: 82 | AD17: 100 | AE17: 87 | AF17: 100 | AG17: =SUM(Y17:AF17)/7 -> 104.14286 | AH17: =(AS17+BA17)/2 -> 90 | AI17: 83 | AJ17: =(AU17+BC17)/2 -> 89.5 | AK17: =(AV17+BD17)/2 -> 43 | AL17: =(AW17+BE17)/2 -> 42 | AM17: =(AX17+BF17)/2 -> 42.5 | AN17: =(AY17+BG17)/2 -> 40 | AO17: =(AZ17+BH17)/2 -> 43 | AP17: =SUM(AH17:AO17)/7 -> 67.571429 | AQ17: =IFERROR(VLOOKUP(A17, PENILAIAN_UAS!A12:B121, 2, FALSE), "NULL") -> 85 | AR17: 80 | AS17: 89 | AU17: 88 | AV17: 86 | AW17: 84 | AX17: 85 | AY17: 80 | AZ17: 86 | BA17: 91 | BB17: 91 | BC17: 91
A18: 60200125056 | B18: MUH. ALIEF RAMADHAN | C18: 1 | D18: 1 | E18: 1 | F18: =IF(AA18>0,1,0) -> 1 | G18: =IF(AB18>0,1,0) -> 1 | H18: =IF(AC18>0,1,0) -> 1 | I18: =IF(AD18>0,1,0) -> 1 | J18: =IF(AE18>0,1,0) -> 1 | M18: =SUM(C18:L18)*10 -> 80 | N18: 0 | O18: 0 | P18: 0 | Q18: 90 | R18: 0 | S18: 0 | T18: 0 | U18: 0 | V18: 0 | W18: 100 | X18: =SUM(N18:W18)/10 -> 19 | Y18: 100 | Z18: 80 | AA18: 80 | AB18: 87 | AC18: 87 | AD18: 100 | AE18: 86 | AF18: 86 | AG18: =SUM(Y18:AF18)/7 -> 100.85714 | AH18: 80 | AI18: =(AT18+BB18)/2 -> 87.5 | AJ18: =(AU18+BC18)/2 -> 88 | AK18: =(AV18+BD18)/2 -> 43 | AL18: =(AW18+BE18)/2 -> 43.5 | AM18: =(AX18+BF18)/2 -> 43 | AN18: =(AY18+BG18)/2 -> 85 | AO18: =(AZ18+BH18)/2 -> 84 | AP18: =SUM(AH18:AO18)/7 -> 79.142857 | AQ18: =IFERROR(VLOOKUP(A18, PENILAIAN_UAS!A13:B122, 2, FALSE), "NULL") -> 91 | AR18: =(Kontrak!$B$6*M18)+(Kontrak!$B$4*X18)+(Kontrak!$B$2*AG18)+(Kontrak!$B$3*AP18)+(Kontrak!$B$5*AQ18) -> 81.114286 | AT18: 84 | AU18: 85 | AV18: 86 | AW18: 87 | AX18: 86 | AY18: 86 | AZ18: 84 | BA18: 91 | BB18: 91 | BC18: 91 | BG18: 84 | BH18: 84
A19: 60200125057 | B19: MUHAMMAD FATHUR RIZQY | C19: 1 | D19: 1 | E19: 1 | F19: =IF(AA19>0,1,0) -> 1 | G19: =IF(AB19>0,1,0) -> 1 | H19: =IF(AC19>0,1,0) -> 1 | I19: =IF(AD19>0,1,0) -> 1 | J19: =IF(AE19>0,1,0) -> 1 | M19: =SUM(C19:L19)*10 -> 80 | N19: 0 | O19: 0 | P19: 0 | Q19: 90 | R19: 0 | S19: 0 | T19: 0 | U19: 0 | V19: 0 | W19: 100 | X19: =SUM(N19:W19)/10 -> 19 | Y19: 85 | Z19: 80 | AA19: 87 | AB19: 100 | AC19: 87 | AD19: 100 | AE19: 87 | AF19: 100 | AG19: =SUM(Y19:AF19)/7 -> 103.71429 | AH19: 80 | AI19: 85,5 | AJ19: 87,5 | AK19: =(AV19+BD19)/2 -> 43 | AL19: =(AW19+BE19)/2 -> 41 | AM19: =(AX19+BF19)/2 -> 42.5 | AN19: =(AY19+BG19)/2 -> 43 | AO19: =(AZ19+BH19)/2 -> 43 | AP19: =SUM(AH19:AO19)/7 -> 41.785714 | AQ19: =IFERROR(VLOOKUP(A19, PENILAIAN_UAS!A14:B123, 2, FALSE), "NULL") -> 84 | AR19: 80 | AV19: 86 | AW19: 82 | AX19: 85 | AY19: 86 | AZ19: 86 | BA19: 91 | BB19: 91 | BC19: 91
A20: 60200125058 | B20: AHMAD AMAR MA'RUF AR ROSYID JUMADDANG | D20: 1 | E20: 1 | F20: =IF(AA20>0,1,0) -> 1 | G20: =IF(AB20>0,1,0) -> 1 | H20: =IF(AC20>0,1,0) -> 1 | I20: =IF(AD20>0,1,0) -> 1 | J20: =IF(AE20>0,1,0) -> 1 | M20: =SUM(C20:L20)*10 -> 70 | N20: 0 | O20: 0 | P20: 0 | Q20: 0 | R20: 0 | S20: 0 | T20: 0 | U20: 0 | V20: 100 | W20: 100 | X20: =SUM(N20:W20)/10 -> 20 | Y20: 80 | Z20: 100 | AA20: 80 | AB20: 100 | AC20: 82 | AD20: 100 | AE20: 87 | AF20: 100 | AG20: =SUM(Y20:AF20)/7 -> 104.14286 | AH20: =(AS20+BA20)/2 -> 90 | AI20: =(AT20+BB20)/2 -> 85.5 | AJ20: =(AU20+BC20)/2 -> 88 | AK20: =(AV20+BD20)/2 -> 89 | AL20: =(AW20+BE20)/2 -> 89 | AM20: =(AX20+BF20)/2 -> 88 | AN20: =(AY20+BG20)/2 -> 43.5 | AO20: =(AZ20+BH20)/2 -> 42 | AP20: =SUM(AH20:AO20)/7 -> 87.857143 | AQ20: =IFERROR(VLOOKUP(A20, PENILAIAN_UAS!A15:B124, 2, FALSE), "NULL") -> 81 | AR20: =(Kontrak!$B$6*M20)+(Kontrak!$B$4*X20)+(Kontrak!$B$2*AG20)+(Kontrak!$B$3*AP20)+(Kontrak!$B$5*AQ20) -> 80.485714 | AS20: 89 | AT20: 80 | AU20: 85 | AV20: 87 | AW20: 87 | AX20: 85 | AY20: 87 | AZ20: 84 | BA20: 91 | BB20: 91 | BC20: 91 | BD20: 91 | BE20: 91 | BF20: 91
A21: 60200125072 | B21: KURNIATI | C21: 1 | D21: 1 | E21: 1 | F21: =IF(AA21>0,1,0) -> 1 | G21: =IF(AB21>0,1,0) -> 1 | H21: =IF(AC21>0,1,0) -> 1 | I21: =IF(AD21>0,1,0) -> 1 | J21: =IF(AE21>0,1,0) -> 1 | M21: =SUM(C21:L21)*10 -> 80 | N21: 0 | O21: 0 | P21: 0 | Q21: 0 | R21: 0 | S21: 0 | T21: 0 | U21: 0 | V21: 0 | W21: 100 | X21: =SUM(N21:W21)/10 -> 10 | Y21: 100 | Z21: 83 | AA21: 100 | AB21: 79 | AC21: 100 | AD21: 100 | AE21: 100 | AF21: 87 | AG21: =SUM(Y21:AF21)/7 -> 107 | AH21: =(AS21+BA21)/2 -> 85.5 | AI21: 80 | AJ21: 0 | AK21: =(AV21+BD21)/2 -> 89 | AL21: =(AW21+BE21)/2 -> 86.5 | AM21: =(AX21+BF21)/2 -> 88.5 | AN21: =(AY21+BG21)/2 -> 42 | AO21: =(AZ21+BH21)/2 -> 42 | AP21: =SUM(AH21:AO21)/7 -> 73.357143 | AQ21: =IFERROR(VLOOKUP(A21, PENILAIAN_UAS!A16:B125, 2, FALSE), "NULL") -> 92 | AR21: =(Kontrak!$B$6*M21)+(Kontrak!$B$4*X21)+(Kontrak!$B$2*AG21)+(Kontrak!$B$3*AP21)+(Kontrak!$B$5*AQ21) -> 80.007143 | AS21: 80 | AU21: 87 | AV21: 87 | AW21: 82 | AX21: 86 | AY21: 84 | AZ21: 84 | BA21: 91 | BB21: 91 | BC21: 91 | BD21: 91 | BE21: 91 | BF21: 91
A22: 60200125079 | B22: RIZADLY SYAHRAZZY | C22: 1 | D22: 1 | E22: 1 | F22: =IF(AA22>0,1,0) -> 0 | G22: =IF(AB22>0,1,0) -> 0 | H22: =IF(AC22>0,1,0) -> 0 | I22: =IF(AD22>0,1,0) -> 1 | J22: =IF(AE22>0,1,0) -> 0 | M22: =SUM(C22:L22)*10 -> 40 | N22: 0 | O22: 0 | P22: 0 | Q22: 0 | R22: 0 | S22: 0 | T22: 0 | U22: 0 | V22: 0 | W22: 100 | X22: =SUM(N22:W22)/10 -> 10 | Y22: 0 | Z22: 0 | AA22: 0 | AB22: 0 | AC22: 0 | AD22: 100 | AE22: 0 | AF22: 0 | AG22: =SUM(Y22:AF22)/7 -> 14.285714 | AH22: =(AS22+BA22)/2 -> 0 | AI22: 0 | AJ22: 0 | AK22: =(AV22+BD22)/2 -> 0 | AL22: =(AW22+BE22)/2 -> 0 | AM22: =(AX22+BF22)/2 -> 0 | AN22: =(AY22+BG22)/2 -> 0 | AO22: =(AZ22+BH22)/2 -> 0 | AP22: =SUM(AH22:AO22)/7 -> 0 | AQ22: =IFERROR(VLOOKUP(A22, PENILAIAN_UAS!A17:B126, 2, FALSE), "NULL") -> 84 | AR22: =(Kontrak!$B$6*M22)+(Kontrak!$B$4*X22)+(Kontrak!$B$2*AG22)+(Kontrak!$B$3*AP22)+(Kontrak!$B$5*AQ22) -> 33.057143
A23: 60200125080 | B23: MUHAMMAD FADHIL SAHARUDDIN | D23: 1 | E23: 1 | F23: =IF(AA23>0,1,0) -> 0 | G23: =IF(AB23>0,1,0) -> 0 | H23: =IF(AC23>0,1,0) -> 0 | I23: =IF(AD23>0,1,0) -> 1 | J23: =IF(AE23>0,1,0) -> 0 | M23: =SUM(C23:L23)*10 -> 30 | N23: 0 | O23: 0 | P23: 0 | Q23: 0 | R23: 0 | S23: 0 | T23: 0 | U23: 0 | V23: 0 | W23: 0 | X23: =SUM(N23:W23)/10 -> 0 | Y23: 0 | Z23: 0 | AA23: 0 | AB23: 0 | AC23: 0 | AD23: 100 | AE23: 0 | AF23: 0 | AG23: =SUM(Y23:AF23)/7 -> 14.285714 | AH23: =(AS23+BA23)/2 -> 0 | AI23: 0 | AJ23: 0 | AK23: =(AV23+BD23)/2 -> 0 | AL23: =(AW23+BE23)/2 -> 0 | AM23: =(AX23+BF23)/2 -> 0 | AN23: =(AY23+BG23)/2 -> 0 | AO23: =(AZ23+BH23)/2 -> 0 | AP23: =SUM(AH23:AO23)/7 -> 0 | AQ23: =IFERROR(VLOOKUP(A23, PENILAIAN_UAS!A18:B127, 2, FALSE), "NULL") -> 0 | AR23: =(Kontrak!$B$6*M23)+(Kontrak!$B$4*X23)+(Kontrak!$B$2*AG23)+(Kontrak!$B$3*AP23)+(Kontrak!$B$5*AQ23) -> 5.8571429
A24: 60200125081 | B24: AZKA ALJIBRA ANDI RIDWAN | C24: 1 | D24: 1 | E24: 1 | F24: =IF(AA24>0,1,0) -> 0 | G24: =IF(AB24>0,1,0) -> 0 | H24: =IF(AC24>0,1,0) -> 0 | I24: =IF(AD24>0,1,0) -> 1 | J24: =IF(AE24>0,1,0) -> 0 | M24: =SUM(C24:L24)*10 -> 40 | N24: 0 | O24: 0 | P24: 0 | Q24: 0 | R24: 0 | S24: 0 | T24: 0 | U24: 0 | V24: 0 | W24: 0 | X24: =SUM(N24:W24)/10 -> 0 | Y24: 0 | Z24: 0 | AA24: 0 | AB24: 0 | AC24: 0 | AD24: 100 | AE24: 0 | AF24: 0 | AG24: =SUM(Y24:AF24)/7 -> 14.285714 | AH24: =(AS24+BA24)/2 -> 0 | AI24: 80 | AJ24: 0 | AK24: =(AV24+BD24)/2 -> 0 | AL24: =(AW24+BE24)/2 -> 0 | AM24: =(AX24+BF24)/2 -> 0 | AN24: =(AY24+BG24)/2 -> 0 | AO24: =(AZ24+BH24)/2 -> 0 | AP24: =SUM(AH24:AO24)/7 -> 11.428571 | AQ24: =IFERROR(VLOOKUP(A24, PENILAIAN_UAS!A19:B128, 2, FALSE), "NULL") -> 0 | AR24: =(Kontrak!$B$6*M24)+(Kontrak!$B$4*X24)+(Kontrak!$B$2*AG24)+(Kontrak!$B$3*AP24)+(Kontrak!$B$5*AQ24) -> 10.285714
A25: 60200125094 | B25: AHMAD ZUHRI AL JAUZI | C25: 1 | D25: 1 | E25: 1 | F25: =IF(AA25>0,1,0) -> 0 | G25: =IF(AB25>0,1,0) -> 0 | H25: =IF(AC25>0,1,0) -> 0 | I25: =IF(AD25>0,1,0) -> 1 | J25: =IF(AE25>0,1,0) -> 0 | M25: =SUM(C25:L25)*10 -> 40 | N25: 0 | O25: 0 | P25: 0 | Q25: 0 | R25: 0 | S25: 0 | T25: 0 | U25: 0 | V25: 0 | W25: 100 | X25: =SUM(N25:W25)/10 -> 10 | Y25: 100 | Z25: 0 | AA25: 0 | AB25: 0 | AC25: 0 | AD25: 100 | AE25: 0 | AF25: 0 | AG25: =SUM(Y25:AF25)/7 -> 28.571429 | AH25: =(AS25+BA25)/2 -> 88 | AI25: =(AT25+BB25)/2 -> 45.5 | AJ25: =(AU25+BC25)/2 -> 88 | AK25: =(AV25+BD25)/2 -> 40 | AL25: =(AW25+BE25)/2 -> 42.5 | AM25: =(AX25+BF25)/2 -> 41 | AN25: =(AY25+BG25)/2 -> 42.5 | AO25: =(AZ25+BH25)/2 -> 0 | AP25: =SUM(AH25:AO25)/7 -> 55.357143 | AQ25: =IFERROR(VLOOKUP(A25, PENILAIAN_UAS!A20:B129, 2, FALSE), "NULL") -> 92 | AR25: 80 | AS25: 85 | AU25: 85 | AV25: 80 | AW25: 85 | AX25: 82 | AY25: 85 | BA25: 91 | BB25: 91 | BC25: 91
A26: 60200125096 | B26: MARIFATULLAH MUSDA | C26: 1 | D26: 1 | E26: 1 | F26: =IF(AA26>0,1,0) -> 1 | G26: =IF(AB26>0,1,0) -> 0 | H26: =IF(AC26>0,1,0) -> 1 | I26: =IF(AD26>0,1,0) -> 1 | J26: =IF(AE26>0,1,0) -> 1 | M26: =SUM(C26:L26)*10 -> 70 | N26: 0 | O26: 0 | P26: 0 | Q26: 90 | R26: 0 | S26: 0 | T26: 0 | U26: 0 | V26: 0 | W26: 100 | X26: =SUM(N26:W26)/10 -> 19 | Y26: 100 | Z26: 80 | AA26: 100 | AB26: 0 | AC26: 100 | AD26: 100 | AE26: 100 | AF26: 0 | AG26: =SUM(Y26:AF26)/7 -> 82.857143 | AH26: 85 | AI26: 80 | AJ26: =(AU26+BC26)/2 -> 88 | AK26: =(AV26+BD26)/2 -> 88.5 | AL26: =(AW26+BE26)/2 -> 88.5 | AM26: =(AX26+BF26)/2 -> 88 | AN26: =(AY26+BG26)/2 -> 85 | AO26: =(AZ26+BH26)/2 -> 42 | AP26: =SUM(AH26:AO26)/7 -> 92.142857 | AQ26: =IFERROR(VLOOKUP(A26, PENILAIAN_UAS!A21:B130, 2, FALSE), "NULL") -> 91 | AR26: =(Kontrak!$B$6*M26)+(Kontrak!$B$4*X26)+(Kontrak!$B$2*AG26)+(Kontrak!$B$3*AP26)+(Kontrak!$B$5*AQ26) -> 80.414286 | AS26: 85 | AT26: 80 | AU26: 85 | AV26: 86 | AW26: 86 | AX26: 85 | AY26: 86 | BA26: 91 | BB26: 91 | BC26: 91 | BD26: 91 | BE26: 91 | BF26: 91 | BG26: 84 | BH26: 84
A27: 60200125102 | B27: MUH. FIRDAUS SHAFAR | C27: 1 | D27: 1 | E27: 1 | F27: =IF(AA27>0,1,0) -> 0 | G27: =IF(AB27>0,1,0) -> 0 | H27: =IF(AC27>0,1,0) -> 0 | I27: =IF(AD27>0,1,0) -> 1 | J27: =IF(AE27>0,1,0) -> 0 | M27: =SUM(C27:L27)*10 -> 40 | N27: 0 | O27: 0 | P27: 0 | Q27: 0 | R27: 0 | S27: 0 | T27: 0 | U27: 0 | V27: 0 | W27: 0 | X27: =SUM(N27:W27)/10 -> 0 | Y27: 0 | Z27: 0 | AA27: 0 | AB27: 0 | AC27: 0 | AD27: 100 | AE27: 0 | AF27: 0 | AG27: =SUM(Y27:AF27)/7 -> 14.285714 | AH27: =(AS27+BA27)/2 -> 0 | AI27: 0 | AJ27: 0 | AK27: =(AV27+BD27)/2 -> 0 | AL27: =(AW27+BE27)/2 -> 0 | AM27: =(AX27+BF27)/2 -> 0 | AN27: =(AY27+BG27)/2 -> 0 | AO27: =(AZ27+BH27)/2 -> 0 | AP27: =SUM(AH27:AO27)/7 -> 0 | AQ27: =IFERROR(VLOOKUP(A27, PENILAIAN_UAS!A22:B131, 2, FALSE), "NULL") -> 0 | AR27: =(Kontrak!$B$6*M27)+(Kontrak!$B$4*X27)+(Kontrak!$B$2*AG27)+(Kontrak!$B$3*AP27)+(Kontrak!$B$5*AQ27) -> 6.8571429
A28: 60200125103 | B28: RAHMAWATI | C28: 1 | D28: 1 | E28: 1 | F28: =IF(AA28>0,1,0) -> 0 | G28: =IF(AB28>0,1,0) -> 1 | H28: =IF(AC28>0,1,0) -> 1 | I28: =IF(AD28>0,1,0) -> 1 | J28: =IF(AE28>0,1,0) -> 1 | M28: =SUM(C28:L28)*10 -> 70 | N28: 0 | O28: 0 | P28: 0 | Q28: 0 | R28: 0 | S28: 0 | T28: 0 | U28: 0 | V28: 0 | W28: 100 | X28: =SUM(N28:W28)/10 -> 10 | Y28: 83 | Z28: 100 | AA28: 0 | AB28: 100 | AC28: 87 | AD28: 100 | AE28: 87 | AF28: 100 | AG28: =SUM(Y28:AF28)/7 -> 93.857143 | AH28: =(AS28+BA28)/2 -> 90 | AI28: 83 | AJ28: =(AU28+BC28)/2 -> 88.5 | AK28: =(AV28+BD28)/2 -> 89 | AL28: =(AW28+BE28)/2 -> 88.5 | AM28: =(AX28+BF28)/2 -> 88 | AN28: =(AY28+BG28)/2 -> 42 | AO28: =(AZ28+BH28)/2 -> 0 | AP28: =SUM(AH28:AO28)/7 -> 81.285714 | AQ28: =IFERROR(VLOOKUP(A28, PENILAIAN_UAS!A23:B132, 2, FALSE), "NULL") -> 84 | AR28: 80 | AS28: 89 | AT28: 89 | AU28: 86 | AV28: 87 | AW28: 86 | AX28: 85 | AY28: 84 | BA28: 91 | BB28: 91 | BC28: 91 | BD28: 91 | BE28: 91 | BF28: 91
A29: 60200125104 | B29: KHALIL AHMAD | C29: 1 | D29: 1 | E29: 1 | F29: =IF(AA29>0,1,0) -> 1 | G29: =IF(AB29>0,1,0) -> 1 | H29: =IF(AC29>0,1,0) -> 1 | I29: =IF(AD29>0,1,0) -> 1 | J29: =IF(AE29>0,1,0) -> 1 | M29: =SUM(C29:L29)*10 -> 80 | N29: 0 | O29: 0 | P29: 0 | Q29: 100 | R29: 0 | S29: 0 | T29: 0 | U29: 0 | V29: 0 | W29: 100 | X29: =SUM(N29:W29)/10 -> 20 | Y29: 100 | Z29: 80 | AA29: 83 | AB29: 83 | AC29: 87 | AD29: 100 | AE29: 85 | AF29: 87 | AG29: =SUM(Y29:AF29)/7 -> 100.71429 | AH29: =(AS29+BA29)/2 -> 90 | AI29: 85 | AJ29: 90 | AK29: =(AV29+BD29)/2 -> 88.5 | AL29: =(AW29+BE29)/2 -> 88.5 | AM29: =(AX29+BF29)/2 -> 88.5 | AN29: =(AY29+BG29)/2 -> 85 | AO29: =(AZ29+BH29)/2 -> 85 | AP29: =SUM(AH29:AO29)/7 -> 100.07143 | AQ29: =IFERROR(VLOOKUP(A29, PENILAIAN_UAS!A24:B133, 2, FALSE), "NULL") -> 91 | AR29: =(Kontrak!$B$6*M29)+(Kontrak!$B$4*X29)+(Kontrak!$B$2*AG29)+(Kontrak!$B$3*AP29)+(Kontrak!$B$5*AQ29) -> 87.464286 | AS29: 89 | AU29: 85 | AV29: 86 | AW29: 86 | AX29: 86 | AY29: 86 | AZ29: 86 | BA29: 91 | BB29: 91 | BC29: 91 | BD29: 91 | BE29: 91 | BF29: 91 | BG29: 84 | BH29: 84
A30: 60200125113 | B30: MUH. ILHAM AR. | C30: 1 | D30: 1 | E30: 1 | F30: =IF(AA30>0,1,0) -> 1 | G30: =IF(AB30>0,1,0) -> 1 | H30: =IF(AC30>0,1,0) -> 1 | I30: =IF(AD30>0,1,0) -> 1 | J30: =IF(AE30>0,1,0) -> 1 | M30: =SUM(C30:L30)*10 -> 80 | N30: 0 | O30: 0 | P30: 0 | Q30: 100 | R30: 0 | S30: 0 | T30: 0 | U30: 0 | V30: 0 | W30: 100 | X30: =SUM(N30:W30)/10 -> 20 | Y30: 80 | Z30: 100 | AA30: 80 | AB30: 100 | AC30: 87 | AD30: 100 | AE30: 100 | AF30: 100 | AG30: =SUM(Y30:AF30)/7 -> 106.71429 | AH30: =(AS30+BA30)/2 -> 90 | AI30: 80 | AJ30: 85 | AK30: =(AV30+BD30)/2 -> 89 | AL30: =(AW30+BE30)/2 -> 89 | AM30: =(AX30+BF30)/2 -> 88 | AN30: =(AY30+BG30)/2 -> 43.5 | AO30: =(AZ30+BH30)/2 -> 42 | AP30: =SUM(AH30:AO30)/7 -> 86.642857 | AQ30: =IFERROR(VLOOKUP(A30, PENILAIAN_UAS!A25:B134, 2, FALSE), "NULL") -> 86 | AR30: =(Kontrak!$B$6*M30)+(Kontrak!$B$4*X30)+(Kontrak!$B$2*AG30)+(Kontrak!$B$3*AP30)+(Kontrak!$B$5*AQ30) -> 83.135714 | AS30: 89 | AT30: 80 | AU30: 85 | AV30: 87 | AW30: 87 | AX30: 85 | AY30: 87 | AZ30: 84 | BA30: 91 | BB30: 91 | BC30: 91 | BD30: 91 | BE30: 91 | BF30: 91
A31: 60200125115 | B31: MUTMAINNAH | D31: 1 | E31: 1 | F31: =IF(AA31>0,1,0) -> 1 | G31: =IF(AB31>0,1,0) -> 1 | H31: =IF(AC31>0,1,0) -> 1 | I31: =IF(AD31>0,1,0) -> 1 | J31: =IF(AE31>0,1,0) -> 1 | M31: =SUM(C31:L31)*10 -> 70 | N31: 0 | O31: 0 | P31: 0 | Q31: 0 | R31: 0 | S31: 0 | T31: 0 | U31: 0 | V31: 0 | W31: 100 | X31: =SUM(N31:W31)/10 -> 10 | Y31: 83 | Z31: 100 | AA31: 80 | AB31: 100 | AC31: 87 | AD31: 100 | AE31: 86 | AF31: 100 | AG31: =SUM(Y31:AF31)/7 -> 105.14286 | AH31: 80 | AI31: 79 | AJ31: =(AU31+BC31)/2 -> 89 | AK31: =(AV31+BD31)/2 -> 41.5 | AL31: =(AW31+BE31)/2 -> 42.5 | AM31: =(AX31+BF31)/2 -> 42.5 | AN31: =(AY31+BG31)/2 -> 43.5 | AO31: =(AZ31+BH31)/2 -> 43 | AP31: =SUM(AH31:AO31)/7 -> 65.857143 | AQ31: =IFERROR(VLOOKUP(A31, PENILAIAN_UAS!A26:B135, 2, FALSE), "NULL") -> 81 | AR31: 80 | AT31: 79 | AU31: 87 | AV31: 83 | AW31: 85 | AX31: 85 | AY31: 87 | AZ31: 86 | BA31: 91 | BB31: 91 | BC31: 91
A32: 60200125123 | B32: ASWANDA ZAHRAN | C32: 1 | D32: 1 | E32: 1 | F32: =IF(AA32>0,1,0) -> 1 | G32: =IF(AB32>0,1,0) -> 1 | H32: =IF(AC32>0,1,0) -> 1 | I32: =IF(AD32>0,1,0) -> 1 | J32: =IF(AE32>0,1,0) -> 1 | M32: =SUM(C32:L32)*10 -> 80 | N32: 0 | O32: 0 | P32: 0 | Q32: 90 | R32: 0 | S32: 0 | T32: 0 | U32: 0 | V32: 0 | W32: 100 | X32: =SUM(N32:W32)/10 -> 19 | Y32: 80 | Z32: 100 | AA32: 87 | AB32: 100 | AC32: 87 | AD32: 100 | AE32: 87 | AF32: 87 | AG32: =SUM(Y32:AF32)/7 -> 104 | AH32: =(AS32+BA32)/2 -> 86.5 | AI32: =(AT32+BB32)/2 -> 89 | AJ32: =(AU32+BC32)/2 -> 89.5 | AK32: =(AV32+BD32)/2 -> 89 | AL32: =(AW32+BE32)/2 -> 88.5 | AM32: =(AX32+BF32)/2 -> 88 | AN32: =(AY32+BG32)/2 -> 43.5 | AO32: =(AZ32+BH32)/2 -> 43 | AP32: =SUM(AH32:AO32)/7 -> 88.142857 | AQ32: =IFERROR(VLOOKUP(A32, PENILAIAN_UAS!A27:B136, 2, FALSE), "NULL") -> 85 | AR32: =(Kontrak!$B$6*M32)+(Kontrak!$B$4*X32)+(Kontrak!$B$2*AG32)+(Kontrak!$B$3*AP32)+(Kontrak!$B$5*AQ32) -> 82.642857 | AS32: 82 | AT32: 87 | AU32: 88 | AV32: 87 | AW32: 86 | AX32: 85 | AY32: 87 | AZ32: 86 | BA32: 91 | BB32: 91 | BC32: 91 | BD32: 91 | BE32: 91 | BF32: 91
A33: 60200125124 | B33: ARFA HASRIL | D33: 1 | E33: 1 | F33: =IF(AA33>0,1,0) -> 0 | G33: =IF(AB33>0,1,0) -> 0 | H33: =IF(AC33>0,1,0) -> 0 | I33: =IF(AD33>0,1,0) -> 1 | J33: =IF(AE33>0,1,0) -> 0 | M33: =SUM(C33:L33)*10 -> 30 | N33: 0 | O33: 0 | P33: 0 | Q33: 90 | R33: 0 | S33: 0 | T33: 0 | U33: 0 | V33: 0 | W33: 100 | X33: =SUM(N33:W33)/10 -> 19 | Y33: 0 | Z33: 75 | AA33: 0 | AB33: 0 | AC33: 0 | AD33: 100 | AE33: 0 | AF33: 0 | AG33: =SUM(Y33:AF33)/7 -> 25 | AH33: =(AS33+BA33)/2 -> 0 | AI33: 0 | AJ33: 0 | AK33: =(AV33+BD33)/2 -> 0 | AL33: =(AW33+BE33)/2 -> 0 | AM33: =(AX33+BF33)/2 -> 0 | AN33: =(AY33+BG33)/2 -> 0 | AO33: =(AZ33+BH33)/2 -> 0 | AP33: =SUM(AH33:AO33)/7 -> 0 | AQ33: =IFERROR(VLOOKUP(A33, PENILAIAN_UAS!A28:B137, 2, FALSE), "NULL") -> 86 | AR33: =(Kontrak!$B$6*M33)+(Kontrak!$B$4*X33)+(Kontrak!$B$2*AG33)+(Kontrak!$B$3*AP33)+(Kontrak!$B$5*AQ33) -> 35.7
A34: 60200125125 | B34: ANDI DINUL | D34: 1 | E34: 1 | F34: =IF(AA34>0,1,0) -> 0 | G34: =IF(AB34>0,1,0) -> 1 | H34: =IF(AC34>0,1,0) -> 0 | I34: =IF(AD34>0,1,0) -> 1 | J34: =IF(AE34>0,1,0) -> 1 | M34: =SUM(C34:L34)*10 -> 50 | N34: 0 | O34: 0 | P34: 0 | Q34: 0 | R34: 0 | S34: 0 | T34: 0 | U34: 0 | V34: 0 | W34: 100 | X34: =SUM(N34:W34)/10 -> 10 | Y34: 84 | Z34: 100 | AB34: 100 | AC34: 0 | AD34: 100 | AE34: 87 | AF34: 100 | AG34: =SUM(Y34:AF34)/7 -> 81.571429 | AH34: =(AS34+BA34)/2 -> 90 | AI34: =(AT34+BB34)/2 -> 88 | AJ34: =(AU34+BC34)/2 -> 89 | AK34: =(AV34+BD34)/2 -> 42 | AL34: =(AW34+BE34)/2 -> 40 | AM34: =(AX34+BF34)/2 -> 42.5 | AN34: =(AY34+BG34)/2 -> 42 | AO34: =(AZ34+BH34)/2 -> 43 | AP34: =SUM(AH34:AO34)/7 -> 68.071429 | AQ34: =IFERROR(VLOOKUP(A34, PENILAIAN_UAS!A29:B138, 2, FALSE), "NULL") -> 0 | AR34: 80 | AS34: 89 | AT34: 85 | AU34: 87 | AV34: 84 | AW34: 80 | AX34: 85 | AY34: 84 | AZ34: 86 | BA34: 91 | BB34: 91 | BC34: 91
A35: 60200125126 | B35: SITI LIRIH SALSABILA | C35: 1 | D35: 1 | E35: 1 | F35: =IF(AA35>0,1,0) -> 1 | G35: =IF(AB35>0,1,0) -> 1 | H35: =IF(AC35>0,1,0) -> 1 | I35: =IF(AD35>0,1,0) -> 1 | J35: =IF(AE35>0,1,0) -> 1 | M35: =SUM(C35:L35)*10 -> 80 | N35: 0 | O35: 0 | P35: 0 | Q35: 0 | R35: 0 | S35: 0 | T35: 0 | U35: 0 | V35: 0 | W35: 100 | X35: =SUM(N35:W35)/10 -> 10 | Y35: 100 | Z35: 80 | AA35: 100 | AB35: 84 | AC35: 100 | AD35: 100 | AE35: 100 | AF35: 87 | AG35: =SUM(Y35:AF35)/7 -> 107.28571 | AH35: 80 | AI35: =(AT35+BB35)/2 -> 85.5 | AJ35: =(AU35+BC35)/2 -> 42.5 | AK35: =(AV35+BD35)/2 -> 42 | AL35: =(AW35+BE35)/2 -> 43 | AM35: =(AX35+BF35)/2 -> 42.5 | AN35: =(AY35+BG35)/2 -> 43.5 | AO35: =(AZ35+BH35)/2 -> 43 | AP35: =SUM(AH35:AO35)/7 -> 60.285714 | AQ35: =IFERROR(VLOOKUP(A35, PENILAIAN_UAS!A30:B139, 2, FALSE), "NULL") -> 86 | AR35: 80 | AS35: 80 | AT35: 80 | AU35: 85 | AV35: 84 | AW35: 86 | AX35: 85 | AY35: 87 | AZ35: 86 | BA35: 91 | BB35: 91
A36: 60200125127 | B36: MUH. BAHRUL ISMAIL | C36: 1 | D36: 1 | E36: 1 | F36: =IF(AA36>0,1,0) -> 1 | G36: =IF(AB36>0,1,0) -> 0 | H36: =IF(AC36>0,1,0) -> 0 | I36: =IF(AD36>0,1,0) -> 1 | J36: =IF(AE36>0,1,0) -> 0 | M36: =SUM(C36:L36)*10 -> 50 | N36: 0 | O36: 0 | P36: 0 | Q36: 90 | R36: 0 | S36: 0 | T36: 0 | U36: 0 | V36: 0 | W36: 100 | X36: =SUM(N36:W36)/10 -> 19 | Y36: 80 | Z36: 100 | AA36: 80 | AB36: 0 | AC36: 0 | AD36: 100 | AE36: 0 | AF36: 0 | AG36: =SUM(Y36:AF36)/7 -> 51.428571 | AH36: =(AS36+BA36)/2 -> 88 | AI36: 80 | AJ36: =(AU36+BC36)/2 -> 88 | AK36: =(AV36+BD36)/2 -> 0 | AL36: =(AW36+BE36)/2 -> 0 | AM36: =(AX36+BF36)/2 -> 0 | AN36: =(AY36+BG36)/2 -> 0 | AO36: =(AZ36+BH36)/2 -> 0 | AP36: =SUM(AH36:AO36)/7 -> 36.571429 | AQ36: =IFERROR(VLOOKUP(A36, PENILAIAN_UAS!A31:B140, 2, FALSE), "NULL") -> 0 | AR36: =(Kontrak!$B$6*M36)+(Kontrak!$B$4*X36)+(Kontrak!$B$2*AG36)+(Kontrak!$B$3*AP36)+(Kontrak!$B$5*AQ36) -> 28.157143 | AS36: 85 | AU36: 85 | BA36: 91 | BB36: 91 | BC36: 91
A37: 60200125128 | B37: NURUL AZIZAH | C37: 1 | D37: 1 | E37: 1 | F37: =IF(AA37>0,1,0) -> 1 | G37: =IF(AB37>0,1,0) -> 1 | H37: =IF(AC37>0,1,0) -> 1 | I37: =IF(AD37>0,1,0) -> 1 | J37: =IF(AE37>0,1,0) -> 1 | M37: =SUM(C37:L37)*10 -> 80 | N37: 0 | O37: 0 | P37: 0 | Q37: 90 | R37: 0 | S37: 0 | T37: 0 | U37: 0 | V37: 0 | W37: 0 | X37: =SUM(N37:W37)/10 -> 9 | Y37: 100 | Z37: 80 | AA37: 100 | AB37: 80 | AC37: 100 | AD37: 100 | AE37: 100 | AF37: 80 | AG37: =SUM(Y37:AF37)/7 -> 105.71429 | AH37: 85.5 | AI37: =(AT37+BB37)/2 -> 41 | AJ37: =(AU37+BC37)/2 -> 44 | AK37: =(AV37+BD37)/2 -> 40.5 | AL37: =(AW37+BE37)/2 -> 40.5 | AM37: =(AX37+BF37)/2 -> 42.5 | AN37: =(AY37+BG37)/2 -> 43 | AO37: =(AZ37+BH37)/2 -> 39.5 | AP37: =SUM(AH37:AO37)/7 -> 53.785714 | AQ37: =IFERROR(VLOOKUP(A37, PENILAIAN_UAS!A32:B141, 2, FALSE), "NULL") -> 81 | AR37: 80 | AT37: 82 | AU37: 88 | AV37: 81 | AW37: 81 | AX37: 85 | AY37: 86 | AZ37: 79 | BA37: 91
A38: 60200125129 | B38: ULFIA TUNNIZA | C38: 1 | D38: 1 | E38: 1 | F38: =IF(AA38>0,1,0) -> 1 | G38: =IF(AB38>0,1,0) -> 1 | H38: =IF(AC38>0,1,0) -> 1 | I38: =IF(AD38>0,1,0) -> 1 | J38: =IF(AE38>0,1,0) -> 1 | M38: =SUM(C38:L38)*10 -> 80 | N38: 0 | O38: 0 | P38: 0 | Q38: 0 | R38: 0 | S38: 0 | T38: 0 | U38: 0 | V38: 0 | W38: 100 | X38: =SUM(N38:W38)/10 -> 10 | Y38: 83 | Z38: 100 | AA38: 80 | AB38: 100 | AC38: 85 | AD38: 100 | AE38: 86 | AF38: 100 | AG38: =SUM(Y38:AF38)/7 -> 104.85714 | AH38: 90 | AI38: 89,5 | AJ38: =(AU38+BC38)/2 -> 89.5 | AK38: =(AV38+BD38)/2 -> 41.5 | AL38: =(AW38+BE38)/2 -> 40 | AM38: =(AX38+BF38)/2 -> 42.5 | AN38: =(AY38+BG38)/2 -> 42 | AO38: =(AZ38+BH38)/2 -> 43 | AP38: =SUM(AH38:AO38)/7 -> 55.5 | AQ38: =IFERROR(VLOOKUP(A38, PENILAIAN_UAS!A33:B142, 2, FALSE), "NULL") -> 86 | AR38: 80 | AU38: 88 | AV38: 83 | AW38: 80 | AX38: 85 | AY38: 84 | AZ38: 86 | BA38: 91 | BB38: 91 | BC38: 91
A39: 60200125153 | B39: MUH. FATURRAHMAN S | C39: 1 | D39: 1 | E39: 1 | F39: =IF(AA39>0,1,0) -> 1 | G39: =IF(AB39>0,1,0) -> 0 | H39: =IF(AC39>0,1,0) -> 0 | I39: =IF(AD39>0,1,0) -> 1 | J39: =IF(AE39>0,1,0) -> 0 | M39: =SUM(C39:L39)*10 -> 50 | N39: 0 | O39: 0 | P39: 0 | Q39: 0 | R39: 0 | S39: 0 | T39: 0 | U39: 0 | V39: 0 | W39: 0 | X39: =SUM(N39:W39)/10 -> 0 | Y39: 0 | Z39: 0 | AA39: 80 | AB39: 0 | AC39: 0 | AD39: 100 | AE39: 0 | AF39: 0 | AG39: =SUM(Y39:AF39)/7 -> 25.714286 | AH39: =(AS39+BA39)/2 -> 0 | AI39: 83 | AJ39: =(AU39+BC39)/2 -> 0 | AK39: =(AV39+BD39)/2 -> 0 | AL39: =(AW39+BE39)/2 -> 0 | AM39: =(AX39+BF39)/2 -> 0 | AN39: =(AY39+BG39)/2 -> 0 | AO39: =(AZ39+BH39)/2 -> 0 | AP39: =SUM(AH39:AO39)/7 -> 11.857143 | AQ39: =IFERROR(VLOOKUP(A39, PENILAIAN_UAS!A34:B143, 2, FALSE), "NULL") -> 0 | AR39: =(Kontrak!$B$6*M39)+(Kontrak!$B$4*X39)+(Kontrak!$B$2*AG39)+(Kontrak!$B$3*AP39)+(Kontrak!$B$5*AQ39) -> 13.7
A40: 60200125155 | B40: NURCHOLIS FIRDAUS MUSLIMIN | C40: 1 | D40: 1 | E40: 1 | F40: =IF(AA40>0,1,0) -> 1 | G40: =IF(AB40>0,1,0) -> 1 | H40: =IF(AC40>0,1,0) -> 1 | I40: =IF(AD40>0,1,0) -> 1 | J40: =IF(AE40>0,1,0) -> 0 | M40: =SUM(C40:L40)*10 -> 70 | N40: 0 | O40: 0 | P40: 0 | Q40: 90 | R40: 0 | S40: 0 | T40: 0 | U40: 0 | V40: 0 | W40: 100 | X40: =SUM(N40:W40)/10 -> 19 | Y40: 82 | Z40: 100 | AA40: 87 | AB40: 100 | AC40: 87 | AD40: 100 | AE40: 0 | AF40: 100 | AG40: =SUM(Y40:AF40)/7 -> 93.714286 | AH40: =(AS40+BA40)/2 -> 45.5 | AI40: =(AT40+BB40)/2 -> 88 | AJ40: =(AU40+BC40)/2 -> 85.5 | AK40: =(AV40+BD40)/2 -> 42 | AL40: =(AW40+BE40)/2 -> 43 | AM40: =(AX40+BF40)/2 -> 43 | AN40: =(AY40+BG40)/2 -> 43 | AO40: =(AZ40+BH40)/2 -> 42 | AP40: =SUM(AH40:AO40)/7 -> 61.714286 | AQ40: =IFERROR(VLOOKUP(A40, PENILAIAN_UAS!A35:B144, 2, FALSE), "NULL") -> 88 | AR40: 80 | AT40: 85 | AU40: 80 | AV40: 84 | AW40: 86 | AX40: 86 | AY40: 86 | AZ40: 84 | BA40: 91 | BB40: 91 | BC40: 91

Sheet KELAS D
A1: KELAS D
A5: NIM | B5: NAMA | C5: Kehadiran | M5: Nilai Kehadiran | N5: Keaktifan | X5: Nilai Keaktifan | Y5: Tugas Pendahuluan | AG5: Nilai TP | AH5: Laporan | AP5: Nilai Laporan | AQ5: Nilai UAS | AR5: Nilai Hasil | AS5: LP Ass1 | BA5: LP Ass2
C6: 1 | D6: 2 | E6: 3 | F6: 4 | G6: 5 | H6: 6 | I6: 7 | J6: 8 | K6: 9 | L6: 10 | N6: 1 | O6: 2 | P6: 3 | Q6: 4 | R6: 5 | S6: 6 | T6: 7 | U6: 8 | V6: 9 | W6: 10 | Y6: 1 | Z6: 2 | AA6: 3 | AB6: 4 | AC6: 5 | AD6: 6 | AE6: 7 | AF6: 8 | AH6: 1 | AI6: 2 | AJ6: 3 | AK6: 4 | AL6: 5 | AM6: 6 | AN6: 7 | AO6: 8 | AS6: 1 | AT6: 2 | AU6: 3 | AV6: 4 | AW6: 5 | AX6: 6 | AY6: 7 | AZ6: 8 | BA6: 1 | BB6: 2 | BC6: 3 | BD6: 4 | BE6: 5 | BF6: 6 | BG6: 7 | BH6: 8
A7: 60200123102 | B7: MUH SYAMSUL JAMIL | C7: 1 | D7: 1 | E7: 1 | F7: =IF(AA7>0,1,0) -> 0 | G7: =IF(AB7>0,1,0) -> 0 | H7: =IF(AC7>0,1,0) -> 0 | I7: =IF(AD7>0,1,0) -> 1 | J7: =IF(AE7>0,1,0) -> 0 | M7: =SUM(C7:L7)*10 -> 40 | N7: 0 | O7: 0 | P7: 0 | Q7: 0 | R7: 0 | S7: 0 | T7: 0 | U7: 0 | V7: 0 | W7: 0 | X7: =SUM(N7:W7)/10 -> 0 | Y7: 0 | Z7: 0 | AA7: 0 | AB7: 0 | AC7: 0 | AD7: 100 | AE7: 0 | AF7: 0 | AG7: =SUM(Y7:AF7)/7 -> 14.285714 | AH7: =(AS7+BA7)/2 -> 0 | AI7: =(AT7+BB7)/2 -> 0 | AJ7: =(AU7+BC7)/2 -> 0 | AK7: =(AV7+BD7)/2 -> 0 | AL7: =(AW7+BE7)/2 -> 0 | AM7: =(AX7+BF7)/2 -> 0 | AN7: =(AY7+BG7)/2 -> 0 | AO7: =(AZ7+BH7)/2 -> 0 | AP7: =SUM(AH7:AO7)/7 -> 0 | AQ7: 86 | AR7: =(Kontrak!$B$6*M7)+(Kontrak!$B$4*X7)+(Kontrak!$B$2*AG7)+(Kontrak!$B$3*AP7)+(Kontrak!$B$5*AQ7) -> 32.657143
A8: 60200125004 | B8: SHAKIRA AL - MAHDALY | C8: 1 | D8: 1 | E8: 1 | F8: =IF(AA8>0,1,0) -> 1 | G8: =IF(AB8>0,1,0) -> 1 | H8: =IF(AC8>0,1,0) -> 1 | I8: =IF(AD8>0,1,0) -> 1 | J8: =IF(AE8>0,1,0) -> 1 | M8: =SUM(C8:L8)*10 -> 80 | N8: 0 | O8: 0 | P8: 0 | Q8: 0 | R8: 0 | S8: 0 | T8: 0 | U8: 0 | V8: 0 | W8: 100 | X8: =SUM(N8:W8)/10 -> 10 | Y8: 100 | Z8: 80 | AA8: 100 | AB8: 82 | AC8: 100 | AD8: 100 | AE8: 87 | AF8: 100 | AG8: =SUM(Y8:AF8)/7 -> 107 | AH8: =(AS8+BA8)/2 -> 90 | AI8: 82 | AJ8: =(AU8+BC8)/2 -> 88 | AK8: =(AV8+BD8)/2 -> 0 | AL8: =(AW8+BE8)/2 -> 41.5 | AM8: =(AX8+BF8)/2 -> 42.5 | AN8: =(AY8+BG8)/2 -> 43 | AO8: =(AZ8+BH8)/2 -> 43 | AP8: =SUM(AH8:AO8)/7 -> 61.428571 | AQ8: 86 | AR8: 80 | AS8: 89 | AT8: 84 | AU8: 85 | AW8: 83 | AX8: 85 | AY8: 86 | AZ8: 86 | BA8: 91 | BB8: 91 | BC8: 91
A9: 60200125012 | B9: ELSA APRILIA | C9: 1 | D9: 1 | E9: 1 | F9: =IF(AA9>0,1,0) -> 0 | G9: =IF(AB9>0,1,0) -> 0 | H9: =IF(AC9>0,1,0) -> 0 | I9: =IF(AD9>0,1,0) -> 1 | J9: =IF(AE9>0,1,0) -> 0 | M9: =SUM(C9:L9)*10 -> 40 | N9: 0 | O9: 0 | P9: 0 | Q9: 0 | R9: 0 | S9: 0 | T9: 0 | U9: 0 | V9: 0 | W9: 100 | X9: =SUM(N9:W9)/10 -> 10 | Y9: 0 | Z9: 80 | AA9: 0 | AB9: 0 | AC9: 0 | AD9: 100 | AE9: 0 | AF9: 0 | AG9: =SUM(Y9:AF9)/7 -> 25.714286 | AH9: =(AS9+BA9)/2 -> 0 | AI9: =(AT9+BB9)/2 -> 0 | AJ9: =(AU9+BC9)/2 -> 0 | AK9: =(AV9+BD9)/2 -> 0 | AL9: =(AW9+BE9)/2 -> 0 | AM9: =(AX9+BF9)/2 -> 0 | AN9: =(AY9+BG9)/2 -> 0 | AO9: =(AZ9+BH9)/2 -> 0 | AP9: =SUM(AH9:AO9)/7 -> 0 | AQ9: 86 | AR9: =(Kontrak!$B$6*M9)+(Kontrak!$B$4*X9)+(Kontrak!$B$2*AG9)+(Kontrak!$B$3*AP9)+(Kontrak!$B$5*AQ9) -> 35.942857
A10: 60200125013 | B10: ZAHRANI PUTRI HUMAIRA | C10: 1 | D10: 1 | E10: 1 | F10: =IF(AA10>0,1,0) -> 0 | G10: =IF(AB10>0,1,0) -> 1 | H10: =IF(AC10>0,1,0) -> 1 | I10: =IF(AD10>0,1,0) -> 1 | J10: =IF(AE10>0,1,0) -> 1 | M10: =SUM(C10:L10)*10 -> 70 | N10: 0 | O10: 80 | P10: 0 | Q10: 0 | R10: 0 | S10: 0 | T10: 0 | U10: 0 | V10: 0 | W10: 100 | X10: =SUM(N10:W10)/10 -> 18 | Y10: 80 | Z10: 100 | AA10: 0 | AB10: 100 | AC10: 82 | AD10: 100 | AE10: 100 | AF10: 87 | AG10: =SUM(Y10:AF10)/7 -> 92.714286 | AH10: =(AS10+BA10)/2 -> 88 | AI10: =(AT10+BB10)/2 -> 45.5 | AJ10: =(AU10+BC10)/2 -> 43 | AK10: =(AV10+BD10)/2 -> 42 | AL10: =(AW10+BE10)/2 -> 42.5 | AM10: =(AX10+BF10)/2 -> 42.5 | AN10: =(AY10+BG10)/2 -> 83 | AO10: =(AZ10+BH10)/2 -> 84.5 | AP10: =SUM(AH10:AO10)/7 -> 67.285714 | AQ10: 86 | AR10: 80 | AS10: 85 | AU10: 86 | AV10: 84 | AW10: 85 | AX10: 85 | AY10: 82 | AZ10: 85 | BA10: 91 | BB10: 91 | BG10: 84 | BH10: 84
A11: 60200125025 | B11: MUHAMMAD ZULFIQAR | C11: 1 | D11: 1 | E11: 1 | F11: =IF(AA11>0,1,0) -> 0 | G11: =IF(AB11>0,1,0) -> 0 | H11: =IF(AC11>0,1,0) -> 0 | I11: =IF(AD11>0,1,0) -> 1 | J11: =IF(AE11>0,1,0) -> 0 | M11: =SUM(C11:L11)*10 -> 40 | N11: 0 | O11: 0 | P11: 0 | Q11: 0 | R11: 0 | S11: 0 | T11: 0 | U11: 0 | V11: 0 | W11: 0 | X11: =SUM(N11:W11)/10 -> 0 | Y11: 0 | Z11: 0 | AA11: 0 | AB11: 0 | AC11: 0 | AD11: 100 | AE11: 0 | AF11: 0 | AG11: =SUM(Y11:AF11)/7 -> 14.285714 | AH11: =(AS11+BA11)/2 -> 0 | AI11: =(AT11+BB11)/2 -> 0 | AJ11: =(AU11+BC11)/2 -> 0 | AK11: =(AV11+BD11)/2 -> 0 | AL11: =(AW11+BE11)/2 -> 0 | AM11: =(AX11+BF11)/2 -> 0 | AN11: =(AY11+BG11)/2 -> 0 | AO11: =(AZ11+BH11)/2 -> 0 | AP11: =SUM(AH11:AO11)/7 -> 0 | AQ11: 86 | AR11: =(Kontrak!$B$6*M11)+(Kontrak!$B$4*X11)+(Kontrak!$B$2*AG11)+(Kontrak!$B$3*AP11)+(Kontrak!$B$5*AQ11) -> 32.657143
A12: 60200125026 | B12: NUR RIZQI ARIFANI HAFID | C12: 1 | D12: 1 | E12: 1 | F12: =IF(AA12>0,1,0) -> 1 | G12: =IF(AB12>0,1,0) -> 1 | H12: =IF(AC12>0,1,0) -> 1 | I12: =IF(AD12>0,1,0) -> 1 | J12: =IF(AE12>0,1,0) -> 1 | M12: =SUM(C12:L12)*10 -> 80 | N12: 0 | O12: 0 | P12: 0 | Q12: 0 | R12: 0 | S12: 0 | T12: 0 | U12: 0 | V12: 0 | W12: 100 | X12: =SUM(N12:W12)/10 -> 10 | Y12: 100 | Z12: 85 | AA12: 100 | AB12: 83 | AC12: 100 | AD12: 100 | AE12: 87 | AF12: 100 | AG12: =SUM(Y12:AF12)/7 -> 107.85714 | AH12: =(AS12+BA12)/2 -> 88 | AI12: 80 | AJ12: =(AU12+BC12)/2 -> 86.5 | AK12: =(AV12+BD12)/2 -> 42 | AL12: =(AW12+BE12)/2 -> 37.5 | AM12: =(AX12+BF12)/2 -> 42.5 | AN12: =(AY12+BG12)/2 -> 83 | AO12: =(AZ12+BH12)/2 -> 84 | AP12: =SUM(AH12:AO12)/7 -> 77.642857 | AQ12: 86 | AR12: =(Kontrak!$B$6*M12)+(Kontrak!$B$4*X12)+(Kontrak!$B$2*AG12)+(Kontrak!$B$3*AP12)+(Kontrak!$B$5*AQ12) -> 79.664286 | AS12: 85 | AU12: 82 | AV12: 84 | AW12: 75 | AX12: 85 | AY12: 82 | AZ12: 84 | BA12: 91 | BB12: 91 | BC12: 91 | BG12: 84 | BH12: 84
A13: 60200125027 | B13: RESKY SUCI RAMADANI | C13: 1 | D13: 1 | E13: 1 | F13: =IF(AA13>0,1,0) -> 0 | G13: =IF(AB13>0,1,0) -> 1 | H13: =IF(AC13>0,1,0) -> 1 | I13: =IF(AD13>0,1,0) -> 1 | J13: =IF(AE13>0,1,0) -> 1 | M13: =SUM(C13:L13)*10 -> 70 | N13: 0 | O13: 0 | P13: 0 | Q13: 0 | R13: 0 | S13: 0 | T13: 0 | U13: 0 | V13: 0 | W13: 100 | X13: =SUM(N13:W13)/10 -> 10 | Y13: 85 | Z13: 100 | AA13: 0 | AB13: 100 | AC13: 82 | AD13: 100 | AE13: 100 | AF13: 87 | AG13: =SUM(Y13:AF13)/7 -> 93.428571 | AH13: =(AS13+BA13)/2 -> 90 | AI13: 85 | AJ13: =(AU13+BC13)/2 -> 86.5 | AK13: =(AV13+BD13)/2 -> 41 | AL13: =(AW13+BE13)/2 -> 43 | AM13: =(AX13+BF13)/2 -> 42.5 | AN13: =(AY13+BG13)/2 -> 43 | AO13: =(AZ13+BH13)/2 -> 42 | AP13: =SUM(AH13:AO13)/7 -> 67.571429 | AQ13: 86 | AR13: 80 | AS13: 89 | AU13: 82 | AV13: 82 | AW13: 86 | AX13: 85 | AY13: 86 | AZ13: 84 | BA13: 91 | BB13: 91 | BC13: 91
A14: 60200125030 | B14: ALFINA | C14: 1 | D14: 1 | E14: 1 | F14: =IF(AA14>0,1,0) -> 1 | G14: =IF(AB14>0,1,0) -> 1 | H14: =IF(AC14>0,1,0) -> 1 | I14: =IF(AD14>0,1,0) -> 1 | J14: =IF(AE14>0,1,0) -> 1 | M14: =SUM(C14:L14)*10 -> 80 | N14: 0 | O14: 0 | P14: 0 | Q14: 0 | R14: 0 | S14: 0 | T14: 0 | U14: 0 | V14: 0 | W14: 100 | X14: =SUM(N14:W14)/10 -> 10 | Y14: 100 | Z14: 80 | AA14: 100 | AB14: 82 | AC14: 100 | AD14: 100 | AE14: 82 | AF14: 100 | AG14: =SUM(Y14:AF14)/7 -> 106.28571 | AH14: =(AS14+BA14)/2 -> 90 | AI14: =(AT14+BB14)/2 -> 87.5 | AJ14: =(AU14+BC14)/2 -> 85.5 | AK14: =(AV14+BD14)/2 -> 0 | AL14: =(AW14+BE14)/2 -> 41 | AM14: =(AX14+BF14)/2 -> 42.5 | AN14: =(AY14+BG14)/2 -> 42 | AO14: =(AZ14+BH14)/2 -> 0 | AP14: =SUM(AH14:AO14)/7 -> 55.5 | AQ14: 86 | AR14: 80 | AS14: 89 | AT14: 84 | AU14: 80 | AW14: 82 | AX14: 85 | AY14: 84 | BA14: 91 | BB14: 91 | BC14: 91
A15: 60200125041 | B15: ARNUM SARTICA | C15: 1 | D15: 1 | E15: 1 | F15: =IF(AA15>0,1,0) -> 1 | G15: =IF(AB15>0,1,0) -> 1 | H15: =IF(AC15>0,1,0) -> 1 | I15: =IF(AD15>0,1,0) -> 1 | J15: =IF(AE15>0,1,0) -> 1 | M15: =SUM(C15:L15)*10 -> 80 | N15: 0 | O15: 0 | P15: 0 | Q15: 0 | R15: 0 | S15: 0 | T15: 0 | U15: 0 | V15: 0 | W15: 0 | X15: =SUM(N15:W15)/10 -> 0 | Y15: 86 | Z15: 100 | AA15: 85 | AB15: 100 | AC15: 80 | AD15: 100 | AE15: 87 | AF15: 100 | AG15: =SUM(Y15:AF15)/7 -> 105.42857 | AH15: =(AS15+BA15)/2 -> 85.5 | AI15: =(AT15+BB15)/2 -> 45.5 | AJ15: 80 | AK15: =(AV15+BD15)/2 -> 42 | AL15: =(AW15+BE15)/2 -> 43 | AM15: =(AX15+BF15)/2 -> 42.5 | AN15: =(AY15+BG15)/2 -> 40 | AO15: =(AZ15+BH15)/2 -> 41 | AP15: =SUM(AH15:AO15)/7 -> 59.928571 | AQ15: 86 | AR15: 80 | AS15: 80 | AU15: 85 | AV15: 84 | AW15: 86 | AX15: 85 | AY15: 80 | AZ15: 82 | BA15: 91 | BB15: 91 | BC15: 91
A16: 60200125043 | B16: REZA KUSUMA | C16: 1 | D16: 1 | E16: 1 | F16: =IF(AA16>0,1,0) -> 0 | G16: =IF(AB16>0,1,0) -> 0 | H16: =IF(AC16>0,1,0) -> 0 | I16: =IF(AD16>0,1,0) -> 1 | J16: =IF(AE16>0,1,0) -> 0 | M16: =SUM(C16:L16)*10 -> 40 | N16: 0 | O16: 0 | P16: 0 | Q16: 0 | R16: 0 | S16: 0 | T16: 0 | U16: 0 | V16: 0 | W16: 0 | X16: =SUM(N16:W16)/10 -> 0 | Y16: 0 | Z16: 0 | AA16: 0 | AB16: 0 | AC16: 0 | AD16: 100 | AE16: 0 | AF16: 0 | AG16: =SUM(Y16:AF16)/7 -> 14.285714 | AH16: =(AS16+BA16)/2 -> 0 | AI16: =(AT16+BB16)/2 -> 0 | AJ16: =(AU16+BC16)/2 -> 0 | AK16: =(AV16+BD16)/2 -> 0 | AL16: =(AW16+BE16)/2 -> 0 | AM16: =(AX16+BF16)/2 -> 0 | AN16: =(AY16+BG16)/2 -> 0 | AO16: =(AZ16+BH16)/2 -> 0 | AP16: =SUM(AH16:AO16)/7 -> 0 | AQ16: 86 | AR16: =(Kontrak!$B$6*M16)+(Kontrak!$B$4*X16)+(Kontrak!$B$2*AG16)+(Kontrak!$B$3*AP16)+(Kontrak!$B$5*AQ16) -> 32.657143
A17: 60200125052 | B17: M. FADIL | C17: 1 | D17: 1 | E17: 1 | F17: =IF(AA17>0,1,0) -> 0 | G17: =IF(AB17>0,1,0) -> 0 | H17: =IF(AC17>0,1,0) -> 0 | I17: =IF(AD17>0,1,0) -> 1 | J17: =IF(AE17>0,1,0) -> 0 | M17: =SUM(C17:L17)*10 -> 40 | N17: 0 | O17: 0 | P17: 0 | Q17: 0 | R17: 0 | S17: 0 | T17: 0 | U17: 0 | V17: 0 | W17: 0 | X17: =SUM(N17:W17)/10 -> 0 | Y17: 0 | Z17: 0 | AA17: 0 | AB17: 0 | AC17: 0 | AD17: 100 | AE17: 0 | AF17: 0 | AG17: =SUM(Y17:AF17)/7 -> 14.285714 | AH17: =(AS17+BA17)/2 -> 0 | AI17: =(AT17+BB17)/2 -> 0 | AJ17: =(AU17+BC17)/2 -> 0 | AK17: =(AV17+BD17)/2 -> 0 | AL17: =(AW17+BE17)/2 -> 0 | AM17: =(AX17+BF17)/2 -> 0 | AN17: =(AY17+BG17)/2 -> 0 | AO17: =(AZ17+BH17)/2 -> 0 | AP17: =SUM(AH17:AO17)/7 -> 0 | AQ17: 86 | AR17: =(Kontrak!$B$6*M17)+(Kontrak!$B$4*X17)+(Kontrak!$B$2*AG17)+(Kontrak!$B$3*AP17)+(Kontrak!$B$5*AQ17) -> 32.657143
A18: 60200125064 | B18: MUTTIARA SARIANTI | C18: 1 | D18: 1 | E18: 1 | F18: =IF(AA18>0,1,0) -> 1 | G18: =IF(AB18>0,1,0) -> 1 | H18: =IF(AC18>0,1,0) -> 1 | I18: =IF(AD18>0,1,0) -> 1 | J18: =IF(AE18>0,1,0) -> 1 | M18: =SUM(C18:L18)*10 -> 80 | N18: 0 | O18: 0 | P18: 0 | Q18: 0 | R18: 0 | S18: 0 | T18: 0 | U18: 0 | V18: 0 | W18: 0 | X18: =SUM(N18:W18)/10 -> 0 | Y18: 100 | Z18: 85 | AA18: 100 | AB18: 80 | AC18: 100 | AD18: 100 | AE18: 100 | AF18: 87 | AG18: =SUM(Y18:AF18)/7 -> 107.42857 | AH18: =(AS18+BA18)/2 -> 88 | AI18: =(AT18+BB18)/2 -> 86.5 | AJ18: =(AU18+BC18)/2 -> 87.5 | AK18: =(AV18+BD18)/2 -> 41.5 | AL18: =(AW18+BE18)/2 -> 40 | AM18: =(AX18+BF18)/2 -> 41 | AN18: =(AY18+BG18)/2 -> 43 | AO18: =(AZ18+BH18)/2 -> 42.5 | AP18: =SUM(AH18:AO18)/7 -> 67.142857 | AQ18: 86 | AR18: 80 | AS18: 85 | AT18: 82 | AU18: 84 | AV18: 83 | AW18: 80 | AX18: 82 | AY18: 86 | AZ18: 85 | BA18: 91 | BB18: 91 | BC18: 91
A19: 60200125065 | B19: SAHRAN | C19: 1 | D19: 1 | E19: 1 | F19: =IF(AA19>0,1,0) -> 0 | G19: =IF(AB19>0,1,0) -> 0 | H19: =IF(AC19>0,1,0) -> 0 | I19: =IF(AD19>0,1,0) -> 1 | J19: =IF(AE19>0,1,0) -> 0 | M19: =SUM(C19:L19)*10 -> 40 | N19: 0 | O19: 0 | P19: 0 | Q19: 0 | R19: 0 | S19: 0 | T19: 0 | U19: 0 | V19: 0 | W19: 0 | X19: =SUM(N19:W19)/10 -> 0 | Y19: 0 | Z19: 0 | AA19: 0 | AB19: 0 | AC19: 0 | AD19: 100 | AE19: 0 | AF19: 0 | AG19: =SUM(Y19:AF19)/7 -> 14.285714 | AH19: =(AS19+BA19)/2 -> 45.5 | AI19: =(AT19+BB19)/2 -> 0 | AJ19: =(AU19+BC19)/2 -> 0 | AK19: =(AV19+BD19)/2 -> 0 | AL19: =(AW19+BE19)/2 -> 0 | AM19: =(AX19+BF19)/2 -> 0 | AN19: =(AY19+BG19)/2 -> 0 | AO19: =(AZ19+BH19)/2 -> 0 | AP19: =SUM(AH19:AO19)/7 -> 6.5 | AQ19: 86 | AR19: =(Kontrak!$B$6*M19)+(Kontrak!$B$4*X19)+(Kontrak!$B$2*AG19)+(Kontrak!$B$3*AP19)+(Kontrak!$B$5*AQ19) -> 34.607143 | BA19: 91
A20: 60200125066 | B20: ALIF BAHTIAR | C20: 1 | D20: 1 | E20: 1 | F20: =IF(AA20>0,1,0) -> 1 | G20: =IF(AB20>0,1,0) -> 1 | H20: =IF(AC20>0,1,0) -> 1 | I20: =IF(AD20>0,1,0) -> 1 | J20: =IF(AE20>0,1,0) -> 1 | M20: =SUM(C20:L20)*10 -> 80 | N20: 0 | O20: 0 | P20: 0 | Q20: 0 | R20: 0 | S20: 0 | T20: 0 | U20: 0 | V20: 0 | W20: 100 | X20: =SUM(N20:W20)/10 -> 10 | Y20: 100 | Z20: 81 | AA20: 100 | AB20: 82 | AC20: 100 | AD20: 100 | AE20: 87 | AF20: 100 | AG20: =SUM(Y20:AF20)/7 -> 107.14286 | AH20: =(AS20+BA20)/2 -> 90 | AI20: =(AT20+BB20)/2 -> 86.5 | AJ20: =(AU20+BC20)/2 -> 86.5 | AK20: =(AV20+BD20)/2 -> 40 | AL20: =(AW20+BE20)/2 -> 40 | AM20: =(AX20+BF20)/2 -> 42.5 | AN20: =(AY20+BG20)/2 -> 43 | AO20: =(AZ20+BH20)/2 -> 43 | AP20: =SUM(AH20:AO20)/7 -> 67.357143 | AQ20: 86 | AR20: 80 | AS20: 89 | AT20: 82 | AU20: 82 | AV20: 80 | AW20: 80 | AX20: 85 | AY20: 86 | AZ20: 86 | BA20: 91 | BB20: 91 | BC20: 91
A21: 60200125067 | B21: MUHAMMAD YASIN | C21: 1 | D21: 1 | E21: 1 | F21: =IF(AA21>0,1,0) -> 1 | G21: =IF(AB21>0,1,0) -> 1 | H21: =IF(AC21>0,1,0) -> 1 | I21: =IF(AD21>0,1,0) -> 1 | J21: =IF(AE21>0,1,0) -> 1 | M21: =SUM(C21:L21)*10 -> 80 | N21: 0 | O21: 0 | P21: 0 | Q21: 0 | R21: 0 | S21: 0 | T21: 0 | U21: 0 | V21: 0 | W21: 0 | X21: =SUM(N21:W21)/10 -> 0 | Y21: 83 | Z21: 100 | AA21: 80 | AB21: 100 | AC21: 82 | AD21: 100 | AE21: 87 | AF21: 100 | AG21: =SUM(Y21:AF21)/7 -> 104.57143 | AH21: =(AS21+BA21)/2 -> 87 | AI21: =(AT21+BB21)/2 -> 87.5 | AJ21: =(AU21+BC21)/2 -> 87.5 | AK21: =(AV21+BD21)/2 -> 86.5 | AL21: =(AW21+BE21)/2 -> 85.5 | AM21: =(AX21+BF21)/2 -> 88 | AN21: =(AY21+BG21)/2 -> 42 | AO21: =(AZ21+BH21)/2 -> 41 | AP21: =SUM(AH21:AO21)/7 -> 86.428571 | AQ21: 86 | AR21: 81 | AS21: 83 | AT21: 84 | AU21: 84 | AV21: 82 | AW21: 80 | AX21: 85 | AY21: 84 | AZ21: 82 | BA21: 91 | BB21: 91 | BC21: 91 | BD21: 91 | BE21: 91 | BF21: 91
A22: 60200125068 | B22: MUHAMMAD FADEL RAFI | C22: 1 | D22: 1 | E22: 1 | F22: =IF(AA22>0,1,0) -> 1 | G22: =IF(AB22>0,1,0) -> 1 | H22: =IF(AC22>0,1,0) -> 1 | I22: =IF(AD22>0,1,0) -> 1 | J22: =IF(AE22>0,1,0) -> 1 | M22: =SUM(C22:L22)*10 -> 80 | N22: 0 | O22: 0 | P22: 0 | Q22: 0 | R22: 0 | S22: 0 | T22: 0 | U22: 0 | V22: 0 | W22: 100 | X22: =SUM(N22:W22)/10 -> 10 | Y22: 100 | Z22: 80 | AA22: 100 | AB22: 80 | AC22: 100 | AD22: 100 | AE22: 100 | AF22: 0 | AG22: =SUM(Y22:AF22)/7 -> 94.285714 | AH22: =(AS22+BA22)/2 -> 90 | AI22: =(AT22+BB22)/2 -> 42 | AJ22: =(AU22+BC22)/2 -> 42.5 | AK22: =(AV22+BD22)/2 -> 42 | AL22: =(AW22+BE22)/2 -> 41 | AM22: =(AX22+BF22)/2 -> 42.5 | AN22: =(AY22+BG22)/2 -> 43 | AO22: =(AZ22+BH22)/2 -> 42.5 | AP22: =SUM(AH22:AO22)/7 -> 55.071429 | AQ22: 86 | AR22: 80 | AS22: 89 | AT22: 84 | AU22: 85 | AV22: 84 | AW22: 82 | AX22: 85 | AY22: 86 | AZ22: 85 | BA22: 91
A23: 60200125071 | B23: FIFI MULIANI | C23: 1 | D23: 1 | E23: 1 | F23: =IF(AA23>0,1,0) -> 0 | G23: =IF(AB23>0,1,0) -> 1 | H23: =IF(AC23>0,1,0) -> 1 | I23: =IF(AD23>0,1,0) -> 1 | J23: =IF(AE23>0,1,0) -> 1 | M23: =SUM(C23:L23)*10 -> 70 | N23: 0 | O23: 0 | P23: 0 | Q23: 0 | R23: 0 | S23: 0 | T23: 0 | U23: 0 | V23: 0 | W23: 100 | X23: =SUM(N23:W23)/10 -> 10 | Y23: 80 | Z23: 100 | AA23: 0 | AB23: 100 | AC23: 82 | AD23: 100 | AE23: 87 | AF23: 100 | AG23: =SUM(Y23:AF23)/7 -> 92.714286 | AH23: =(AS23+BA23)/2 -> 44.5 | AI23: 85 | AJ23: =(AU23+BC23)/2 -> 85.5 | AK23: =(AV23+BD23)/2 -> 40 | AL23: =(AW23+BE23)/2 -> 37.5 | AM23: =(AX23+BF23)/2 -> 42.5 | AN23: =(AY23+BG23)/2 -> 43 | AO23: =(AZ23+BH23)/2 -> 42 | AP23: =SUM(AH23:AO23)/7 -> 60 | AQ23: 86 | AR23: 80 | AS23: 89 | AU23: 80 | AV23: 80 | AW23: 75 | AX23: 85 | AY23: 86 | AZ23: 84 | BB23: 91 | BC23: 91
A24: 60200125076 | B24: MUHAMMAD SALMAN | C24: 1 | D24: 1 | E24: 1 | F24: =IF(AA24>0,1,0) -> 1 | G24: =IF(AB24>0,1,0) -> 1 | H24: =IF(AC24>0,1,0) -> 1 | I24: =IF(AD24>0,1,0) -> 1 | J24: =IF(AE24>0,1,0) -> 1 | M24: =SUM(C24:L24)*10 -> 80 | N24: 0 | O24: 0 | P24: 0 | Q24: 0 | R24: 0 | S24: 0 | T24: 0 | U24: 0 | V24: 0 | W24: 100 | X24: =SUM(N24:W24)/10 -> 10 | Y24: 100 | Z24: 86 | AA24: 100 | AB24: 82 | AC24: 100 | AD24: 100 | AE24: 100 | AF24: 85 | AG24: =SUM(Y24:AF24)/7 -> 107.57143 | AH24: =(AS24+BA24)/2 -> 90 | AI24: =(AT24+BB24)/2 -> 0 | AJ24: =(AU24+BC24)/2 -> 40 | AK24: =(AV24+BD24)/2 -> 41 | AL24: =(AW24+BE24)/2 -> 40 | AM24: =(AX24+BF24)/2 -> 40 | AN24: =(AY24+BG24)/2 -> 82 | AO24: =(AZ24+BH24)/2 -> 82.5 | AP24: =SUM(AH24:AO24)/7 -> 59.357143 | AQ24: 86 | AR24: 80 | AS24: 89 | AU24: 80 | AV24: 82 | AW24: 80 | AX24: 80 | AY24: 80 | AZ24: 81 | BA24: 91 | BG24: 84 | BH24: 84
A25: 60200125082 | B25: FAIZ ABDUL AZIZ | C25: 1 | D25: 1 | E25: 1 | F25: =IF(AA25>0,1,0) -> 1 | G25: =IF(AB25>0,1,0) -> 1 | H25: =IF(AC25>0,1,0) -> 1 | I25: =IF(AD25>0,1,0) -> 1 | J25: =IF(AE25>0,1,0) -> 1 | M25: =SUM(C25:L25)*10 -> 80 | N25: 0 | O25: 0 | P25: 0 | Q25: 0 | R25: 0 | S25: 0 | T25: 0 | U25: 0 | V25: 0 | W25: 100 | X25: =SUM(N25:W25)/10 -> 10 | Y25: 100 | Z25: 85 | AA25: 100 | AB25: 82 | AC25: 100 | AD25: 100 | AE25: 87 | AF25: 100 | AG25: =SUM(Y25:AF25)/7 -> 107.71429 | AH25: =(AS25+BA25)/2 -> 90 | AI25: 80 | AJ25: =(AU25+BC25)/2 -> 87.5 | AK25: =(AV25+BD25)/2 -> 42 | AL25: =(AW25+BE25)/2 -> 42 | AM25: =(AX25+BF25)/2 -> 42.5 | AN25: =(AY25+BG25)/2 -> 43 | AO25: =(AZ25+BH25)/2 -> 43 | AP25: =SUM(AH25:AO25)/7 -> 67.142857 | AQ25: 86 | AR25: 80 | AS25: 89 | AT25: 83 | AU25: 84 | AV25: 84 | AW25: 84 | AX25: 85 | AY25: 86 | AZ25: 86 | BA25: 91 | BB25: 91 | BC25: 91
A26: 60200125089 | B26: RESMI MULIANA | C26: 1 | D26: 1 | E26: 1 | F26: =IF(AA26>0,1,0) -> 0 | G26: =IF(AB26>0,1,0) -> 1 | H26: =IF(AC26>0,1,0) -> 1 | I26: =IF(AD26>0,1,0) -> 1 | J26: =IF(AE26>0,1,0) -> 1 | M26: =SUM(C26:L26)*10 -> 70 | N26: 0 | O26: 0 | P26: 0 | Q26: 0 | R26: 0 | S26: 0 | T26: 0 | U26: 0 | V26: 0 | W26: 100 | X26: =SUM(N26:W26)/10 -> 10 | Y26: 80 | Z26: 100 | AA26: 0 | AB26: 100 | AC26: 86 | AD26: 100 | AE26: 87 | AF26: 100 | AG26: =SUM(Y26:AF26)/7 -> 93.285714 | AH26: =(AS26+BA26)/2 -> 88.5 | AI26: =(AT26+BB26)/2 -> 45.5 | AJ26: =(AU26+BC26)/2 -> 88.5 | AK26: =(AV26+BD26)/2 -> 41 | AL26: =(AW26+BE26)/2 -> 42 | AM26: =(AX26+BF26)/2 -> 42.5 | AN26: =(AY26+BG26)/2 -> 84 | AO26: =(AZ26+BH26)/2 -> 85 | AP26: =SUM(AH26:AO26)/7 -> 73.857143 | AQ26: 86 | AR26: 80 | AS26: 86 | AU26: 86 | AV26: 82 | AW26: 84 | AX26: 85 | AY26: 84 | AZ26: 86 | BA26: 91 | BB26: 91 | BC26: 91 | BG26: 84 | BH26: 84
A27: 60200125090 | B27: MUHAMMAD REZHA NIZAR | C27: 1 | D27: 1 | E27: 1 | F27: =IF(AA27>0,1,0) -> 1 | G27: =IF(AB27>0,1,0) -> 1 | H27: =IF(AC27>0,1,0) -> 1 | I27: =IF(AD27>0,1,0) -> 1 | J27: =IF(AE27>0,1,0) -> 1 | M27: =SUM(C27:L27)*10 -> 80 | N27: 0 | O27: 0 | P27: 0 | Q27: 0 | R27: 0 | S27: 0 | T27: 0 | U27: 0 | V27: 0 | W27: 100 | X27: =SUM(N27:W27)/10 -> 10 | Y27: 100 | Z27: 85 | AA27: 100 | AB27: 82 | AC27: 100 | AD27: 100 | AE27: 87 | AF27: 100 | AG27: =SUM(Y27:AF27)/7 -> 107.71429 | AH27: =(AS27+BA27)/2 -> 90 | AI27: 83 | AJ27: =(AU27+BC27)/2 -> 87.5 | AK27: =(AV27+BD27)/2 -> 41 | AL27: =(AW27+BE27)/2 -> 40 | AM27: =(AX27+BF27)/2 -> 42.5 | AN27: =(AY27+BG27)/2 -> 43 | AO27: =(AZ27+BH27)/2 -> 43 | AP27: =SUM(AH27:AO27)/7 -> 67.142857 | AQ27: 86 | AR27: 80 | AS27: 89 | AT27: 82 | AU27: 84 | AV27: 82 | AW27: 80 | AX27: 85 | AY27: 86 | AZ27: 86 | BA27: 91 | BB27: 91 | BC27: 91
A28: 60200125092 | B28: MUH. AHNAF FAIZUL ANWAR | C28: 1 | D28: 1 | E28: 1 | F28: =IF(AA28>0,1,0) -> 0 | G28: =IF(AB28>0,1,0) -> 0 | H28: =IF(AC28>0,1,0) -> 0 | I28: =IF(AD28>0,1,0) -> 1 | J28: =IF(AE28>0,1,0) -> 0 | M28: =SUM(C28:L28)*10 -> 40 | N28: 0 | O28: 0 | P28: 0 | Q28: 0 | R28: 0 | S28: 0 | T28: 0 | U28: 0 | V28: 0 | W28: 0 | X28: =SUM(N28:W28)/10 -> 0 | Y28: 0 | Z28: 0 | AA28: 0 | AB28: 0 | AC28: 0 | AD28: 100 | AE28: 0 | AF28: 0 | AG28: =SUM(Y28:AF28)/7 -> 14.285714 | AH28: =(AS28+BA28)/2 -> 0 | AI28: =(AT28+BB28)/2 -> 0 | AJ28: =(AU28+BC28)/2 -> 0 | AK28: =(AV28+BD28)/2 -> 0 | AL28: =(AW28+BE28)/2 -> 0 | AM28: =(AX28+BF28)/2 -> 0 | AN28: =(AY28+BG28)/2 -> 0 | AO28: =(AZ28+BH28)/2 -> 0 | AP28: =SUM(AH28:AO28)/7 -> 0 | AQ28: 86 | AR28: =(Kontrak!$B$6*M28)+(Kontrak!$B$4*X28)+(Kontrak!$B$2*AG28)+(Kontrak!$B$3*AP28)+(Kontrak!$B$5*AQ28) -> 32.657143
A29: 60200125093 | B29: NUR FADHILLAH RAJAB | C29: 1 | D29: 1 | E29: 1 | F29: =IF(AA29>0,1,0) -> 1 | G29: =IF(AB29>0,1,0) -> 1 | H29: =IF(AC29>0,1,0) -> 1 | I29: =IF(AD29>0,1,0) -> 1 | J29: =IF(AE29>0,1,0) -> 1 | M29: =SUM(C29:L29)*10 -> 80 | N29: 0 | O29: 0 | P29: 0 | Q29: 0 | R29: 0 | S29: 0 | T29: 0 | U29: 0 | V29: 0 | W29: 0 | X29: =SUM(N29:W29)/10 -> 0 | Y29: 80 | Z29: 100 | AA29: 84 | AB29: 100 | AC29: 82 | AD29: 100 | AE29: 87 | AF29: 100 | AG29: =SUM(Y29:AF29)/7 -> 104.71429 | AH29: =(AS29+BA29)/2 -> 90 | AI29: =(AT29+BB29)/2 -> 85.5 | AJ29: =(AU29+BC29)/2 -> 90 | AK29: =(AV29+BD29)/2 -> 42 | AL29: =(AW29+BE29)/2 -> 37.5 | AM29: =(AX29+BF29)/2 -> 42.5 | AN29: =(AY29+BG29)/2 -> 43 | AO29: =(AZ29+BH29)/2 -> 40 | AP29: =SUM(AH29:AO29)/7 -> 67.214286 | AQ29: 86 | AR29: 80 | AS29: 89 | AT29: 80 | AU29: 89 | AV29: 84 | AW29: 75 | AX29: 85 | AY29: 86 | AZ29: 80 | BA29: 91 | BB29: 91 | BC29: 91
A30: 60200125097 | B30: MUH. RASYA ASHABUL KAHFI | C30: 1 | D30: 1 | E30: 1 | F30: =IF(AA30>0,1,0) -> 0 | G30: =IF(AB30>0,1,0) -> 0 | H30: =IF(AC30>0,1,0) -> 0 | I30: =IF(AD30>0,1,0) -> 1 | J30: =IF(AE30>0,1,0) -> 0 | M30: =SUM(C30:L30)*10 -> 40 | N30: 0 | O30: 0 | P30: 0 | Q30: 0 | R30: 0 | S30: 0 | T30: 0 | U30: 0 | V30: 0 | W30: 0 | X30: =SUM(N30:W30)/10 -> 0 | Y30: 100 | Z30: 0 | AA30: 0 | AB30: 0 | AC30: 0 | AD30: 100 | AE30: 0 | AF30: 0 | AG30: =SUM(Y30:AF30)/7 -> 28.571429 | AH30: =(AS30+BA30)/2 -> 45.5 | AI30: =(AT30+BB30)/2 -> 0 | AJ30: =(AU30+BC30)/2 -> 0 | AK30: =(AV30+BD30)/2 -> 0 | AL30: =(AW30+BE30)/2 -> 0 | AM30: =(AX30+BF30)/2 -> 0 | AN30: =(AY30+BG30)/2 -> 0 | AO30: =(AZ30+BH30)/2 -> 0 | AP30: =SUM(AH30:AO30)/7 -> 6.5 | AQ30: 86 | AR30: =(Kontrak!$B$6*M30)+(Kontrak!$B$4*X30)+(Kontrak!$B$2*AG30)+(Kontrak!$B$3*AP30)+(Kontrak!$B$5*AQ30) -> 37.464286 | BA30: 91
A31: 60200125108 | B31: KHAERIL AKRAM | C31: 1 | D31: 1 | E31: 1 | F31: =IF(AA31>0,1,0) -> 1 | G31: =IF(AB31>0,1,0) -> 1 | H31: =IF(AC31>0,1,0) -> 1 | I31: =IF(AD31>0,1,0) -> 1 | J31: =IF(AE31>0,1,0) -> 1 | M31: =SUM(C31:L31)*10 -> 80 | N31: 0 | O31: 0 | P31: 0 | Q31: 0 | R31: 0 | S31: 0 | T31: 0 | U31: 0 | V31: 0 | W31: 100 | X31: =SUM(N31:W31)/10 -> 10 | Y31: 100 | Z31: 85 | AA31: 100 | AB31: 80 | AC31: 100 | AD31: 100 | AE31: 87 | AF31: 87 | AG31: =SUM(Y31:AF31)/7 -> 105.57143 | AH31: =(AS31+BA31)/2 -> 90 | AI31: =(AT31+BB31)/2 -> 85.5 | AJ31: =(AU31+BC31)/2 -> 89 | AK31: =(AV31+BD31)/2 -> 43 | AL31: =(AW31+BE31)/2 -> 43 | AM31: =(AX31+BF31)/2 -> 42.5 | AN31: =(AY31+BG31)/2 -> 85 | AO31: =(AZ31+BH31)/2 -> 85 | AP31: =SUM(AH31:AO31)/7 -> 80.428571 | AQ31: 86 | AR31: =(Kontrak!$B$6*M31)+(Kontrak!$B$4*X31)+(Kontrak!$B$2*AG31)+(Kontrak!$B$3*AP31)+(Kontrak!$B$5*AQ31) -> 80.042857 | AS31: 89 | AT31: 80 | AU31: 87 | AV31: 86 | AW31: 86 | AX31: 85 | AY31: 86 | AZ31: 86 | BA31: 91 | BB31: 91 | BC31: 91 | BG31: 84 | BH31: 84
A32: 60200125109 | B32: ANDI MUH. RIZALDI | C32: 1 | D32: 1 | E32: 1 | F32: =IF(AA32>0,1,0) -> 1 | G32: =IF(AB32>0,1,0) -> 1 | H32: =IF(AC32>0,1,0) -> 1 | I32: =IF(AD32>0,1,0) -> 1 | J32: =IF(AE32>0,1,0) -> 1 | M32: =SUM(C32:L32)*10 -> 80 | N32: 0 | O32: 0 | P32: 0 | Q32: 0 | R32: 0 | S32: 0 | T32: 0 | U32: 0 | V32: 0 | W32: 100 | X32: =SUM(N32:W32)/10 -> 10 | Y32: 0 | Z32: 100 | AA32: 80 | AB32: 100 | AC32: 80 | AD32: 100 | AE32: 100 | AF32: 87 | AG32: =SUM(Y32:AF32)/7 -> 92.428571 | AH32: =(AS32+BA32)/2 -> 88.5 | AI32: =(AT32+BB32)/2 -> 88 | AJ32: =(AU32+BC32)/2 -> 87.5 | AK32: =(AV32+BD32)/2 -> 43 | AL32: =(AW32+BE32)/2 -> 40 | AM32: =(AX32+BF32)/2 -> 42.5 | AN32: =(AY32+BG32)/2 -> 42.5 | AO32: =(AZ32+BH32)/2 -> 42 | AP32: =SUM(AH32:AO32)/7 -> 67.714286 | AQ32: 86 | AR32: 80 | AS32: 86 | AT32: 85 | AU32: 84 | AV32: 86 | AW32: 80 | AX32: 85 | AY32: 85 | AZ32: 84 | BA32: 91 | BB32: 91 | BC32: 91
A33: 60200125110 | B33: AFIFAH AYLA NURULIZZAH | C33: 1 | D33: 1 | E33: 1 | F33: =IF(AA33>0,1,0) -> 1 | G33: =IF(AB33>0,1,0) -> 1 | H33: =IF(AC33>0,1,0) -> 1 | I33: =IF(AD33>0,1,0) -> 1 | J33: =IF(AE33>0,1,0) -> 1 | M33: =SUM(C33:L33)*10 -> 80 | N33: 0 | O33: 0 | P33: 0 | Q33: 0 | R33: 0 | S33: 0 | T33: 0 | U33: 0 | V33: 0 | W33: 100 | X33: =SUM(N33:W33)/10 -> 10 | Y33: 100 | Z33: 85 | AA33: 100 | AB33: 82 | AC33: 100 | AD33: 100 | AE33: 87 | AF33: 0 | AG33: =SUM(Y33:AF33)/7 -> 93.428571 | AH33: =(AS33+BA33)/2 -> 90 | AI33: 80 | AJ33: =(AU33+BC33)/2 -> 87.5 | AK33: =(AV33+BD33)/2 -> 41.5 | AL33: =(AW33+BE33)/2 -> 43 | AM33: =(AX33+BF33)/2 -> 42.5 | AN33: =(AY33+BG33)/2 -> 85 | AO33: =(AZ33+BH33)/2 -> 85 | AP33: =SUM(AH33:AO33)/7 -> 79.214286 | AQ33: 86 | AR33: 80 | AS33: 89 | AU33: 84 | AV33: 83 | AW33: 86 | AX33: 85 | AY33: 86 | AZ33: 86 | BA33: 91 | BB33: 91 | BC33: 91 | BG33: 84 | BH33: 84
A34: 60200125138 | B34: ZALZABILA AMANDA PUTRI | C34: 1 | D34: 1 | E34: 1 | F34: =IF(AA34>0,1,0) -> 1 | G34: =IF(AB34>0,1,0) -> 1 | H34: =IF(AC34>0,1,0) -> 1 | I34: =IF(AD34>0,1,0) -> 1 | J34: =IF(AE34>0,1,0) -> 1 | M34: =SUM(C34:L34)*10 -> 80 | N34: 0 | O34: 0 | P34: 0 | Q34: 0 | R34: 0 | S34: 0 | T34: 0 | U34: 0 | V34: 0 | W34: 0 | X34: =SUM(N34:W34)/10 -> 0 | Y34: 100 | Z34: 84 | AA34: 85 | AB34: 86 | AC34: 82 | AD34: 100 | AE34: 100 | AF34: 87 | AG34: =SUM(Y34:AF34)/7 -> 103.42857 | AH34: =(AS34+BA34)/2 -> 0 | AI34: =(AT34+BB34)/2 -> 0 | AJ34: =(AU34+BC34)/2 -> 0 | AK34: =(AV34+BD34)/2 -> 0 | AL34: =(AW34+BE34)/2 -> 0 | AM34: =(AX34+BF34)/2 -> 42.5 | AN34: =(AY34+BG34)/2 -> 42.5 | AO34: =(AZ34+BH34)/2 -> 0 | AP34: =SUM(AH34:AO34)/7 -> 12.142857 | AQ34: 86 | AR34: 80 | AX34: 85 | AY34: 85
